{
	icon: {
		components: {
			"ftbquests:icon": "chalk:block/mark/house"
		}
		id: "ftbquests:custom_icon"
	}
	id: "3FFDFA44781533D7"
	loot_size: 1
	order_index: 6
	rewards: [
		{ id: "3CD1F349C41904D0", item: { components: { "bagofyurting:radius": 4, "bagofyurting:yurtdata": { data: [ { pos: [I; 3, 6, 3 ], state: 0 }, { pos: [I; 0, 0, 0 ], state: 1 }, { pos: [I; -1, 0, 0 ], state: 1 }, { pos: [I; 4, 6, 3 ], state: 2 }, { pos: [I; 3, 4, 2 ], state: 3 }, { pos: [I; 1, 0, 0 ], state: 1 }, { pos: [I; -2, 0, 0 ], state: 1 }, { pos: [I; 3, 2, 1 ], state: 4 }, { pos: [I; 2, 0, 0 ], state: 1 }, { pos: [I; -3, 0, 0 ], state: 5 }, { pos: [I; 3, 0, 0 ], state: 5 }, { pos: [I; -4, 0, 0 ], state: 5 }, { pos: [I; 4, 0, 0 ], state: 5 }, { pos: [I; -3, 7, 3 ], state: 6 }, { pos: [I; -4, 5, 2 ], state: 7 }, { pos: [I; -2, 7, 3 ], state: 8 }, { pos: [I; -3, 5, 2 ], state: 9 }, { pos: [I; -2, 5, 2 ], state: 1 }, { pos: [I; -3, 3, 1 ], state: 4 }, { pos: [I; 0, 7, 3 ], state: 0 }, { pos: [I; -1, 5, 2 ], state: 1 }, { pos: [I; -2, 3, 1 ], state: 10 }, { pos: [I; -3, 1, 0 ], state: 11 }, { pos: [I; 0, 5, 2 ], state: 1 }, { pos: [I; 2, 7, 3 ], state: 8 }, { pos: [I; 1, 5, 2 ], state: 1 }, { pos: [I; 3, 7, 3 ], state: 6 }, { pos: [I; 2, 5, 2 ], state: 1 }, { pos: [I; 3, 5, 2 ], state: 9 }, { nbt: { Items: [ ], TransferCooldown: 0 }, pos: [I; 1, 1, 0 ], state: 12 }, { pos: [I; 4, 5, 2 ], state: 7 }, { pos: [I; 3, 3, 1 ], state: 4 }, { pos: [I; 3, 1, 0 ], state: 3 }, { pos: [I; -4, 6, 2 ], state: 13 }, { pos: [I; -1, 8, 3 ], state: 6 }, { pos: [I; -3, 4, 1 ], state: 4 }, { pos: [I; 0, 8, 3 ], state: 6 }, { pos: [I; -3, 2, 0 ], state: 14 }, { pos: [I; 1, 8, 3 ], state: 6 }, { pos: [I; 4, 6, 2 ], state: 2 }, { pos: [I; 3, 4, 1 ], state: 4 }, { pos: [I; 3, 2, 0 ], state: 15 }, { pos: [I; -3, 7, 2 ], state: 6 }, { pos: [I; -4, 5, 1 ], state: 16 }, { pos: [I; -2, 7, 2 ], state: 8 }, { pos: [I; -3, 5, 1 ], state: 9 }, { pos: [I; -2, 5, 1 ], state: 1 }, { pos: [I; -3, 3, 0 ], state: 17 }, { pos: [I; -1, 5, 1 ], state: 1 }, { pos: [I; 0, 5, 1 ], state: 1 }, { pos: [I; 2, 7, 2 ], state: 8 }, { pos: [I; 1, 5, 1 ], state: 1 }, { pos: [I; 3, 7, 2 ], state: 6 }, { pos: [I; 2, 5, 1 ], state: 1 }, { pos: [I; 3, 5, 1 ], state: 9 }, { pos: [I; 4, 5, 1 ], state: 18 }, { pos: [I; 3, 3, 0 ], state: 19 }, { pos: [I; -4, 6, 1 ], state: 13 }, { pos: [I; -1, 8, 2 ], state: 6 }, { pos: [I; -3, 4, 0 ], state: 11 }, { pos: [I; 0, 8, 2 ], state: 6 }, { pos: [I; 1, 8, 2 ], state: 6 }, { pos: [I; 0, 4, 0 ], state: 20 }, { pos: [I; 4, 6, 1 ], state: 2 }, { pos: [I; 3, 4, 0 ], state: 3 }, { pos: [I; -3, 7, 1 ], state: 6 }, { pos: [I; -4, 5, 0 ], state: 7 }, { pos: [I; -2, 7, 1 ], state: 8 }, { pos: [I; -3, 5, 0 ], state: 9 }, { pos: [I; -2, 5, 0 ], state: 1 }, { pos: [I; -1, 5, 0 ], state: 1 }, { pos: [I; 0, 5, 0 ], state: 1 }, { pos: [I; 2, 7, 1 ], state: 8 }, { pos: [I; 1, 5, 0 ], state: 1 }, { pos: [I; 3, 7, 1 ], state: 6 }, { pos: [I; 2, 5, 0 ], state: 1 }, { pos: [I; 3, 5, 0 ], state: 9 }, { pos: [I; 4, 5, 0 ], state: 7 }, { pos: [I; -4, 6, 0 ], state: 13 }, { pos: [I; -1, 8, 1 ], state: 6 }, { pos: [I; 0, 8, 1 ], state: 6 }, { pos: [I; 1, 8, 1 ], state: 6 }, { pos: [I; 4, 6, 0 ], state: 2 }, { pos: [I; -3, 7, 0 ], state: 6 }, { pos: [I; -2, 7, 0 ], state: 8 }, { pos: [I; 1, 7, 0 ], state: 8 }, { pos: [I; 2, 7, 0 ], state: 8 }, { pos: [I; 3, 7, 0 ], state: 6 }, { pos: [I; -1, 8, 0 ], state: 6 }, { pos: [I; 0, 8, 0 ], state: 6 }, { pos: [I; 1, 8, 0 ], state: 6 }, { pos: [I; 1, 8, -4 ], state: 21 }, { pos: [I; 0, 8, -4 ], state: 21 }, { pos: [I; -1, 8, -4 ], state: 21 }, { pos: [I; 3, 7, -4 ], state: 21 }, { pos: [I; 2, 7, -4 ], state: 9 }, { pos: [I; 1, 7, -4 ], state: 9 }, { pos: [I; 0, 7, -4 ], state: 7 }, { pos: [I; -1, 7, -4 ], state: 9 }, { pos: [I; -2, 7, -4 ], state: 9 }, { pos: [I; -3, 7, -4 ], state: 21 }, { pos: [I; 4, 6, -4 ], state: 22 }, { pos: [I; 3, 6, -4 ], state: 16 }, { pos: [I; 2, 6, -4 ], state: 7 }, { pos: [I; 1, 8, -3 ], state: 6 }, { pos: [I; 0, 8, -3 ], state: 6 }, { pos: [I; -1, 8, -3 ], state: 6 }, { pos: [I; -2, 6, -4 ], state: 7 }, { pos: [I; -3, 6, -4 ], state: 18 }, { pos: [I; -4, 6, -4 ], state: 23 }, { pos: [I; 4, 5, -4 ], state: 7 }, { pos: [I; 3, 7, -3 ], state: 6 }, { pos: [I; 2, 5, -4 ], state: 24 }, { pos: [I; 2, 7, -3 ], state: 8 }, { pos: [I; 1, 5, -4 ], state: 24 }, { pos: [I; 0, 7, -3 ], state: 0 }, { pos: [I; -1, 5, -4 ], state: 24 }, { pos: [I; -2, 5, -4 ], state: 24 }, { pos: [I; -2, 7, -3 ], state: 25 }, { pos: [I; -3, 7, -3 ], state: 6 }, { pos: [I; -4, 5, -4 ], state: 7 }, { pos: [I; 4, 6, -3 ], state: 2 }, { pos: [I; 3, 6, -3 ], state: 0 }, { pos: [I; 2, 6, -3 ], state: 0 }, { pos: [I; 1, 4, -4 ], state: 26 }, { pos: [I; 1, 6, -3 ], state: 0 }, { pos: [I; 1, 8, -2 ], state: 6 }, { pos: [I; 0, 6, -3 ], state: 0 }, { pos: [I; -1, 4, -4 ], state: 26 }, { pos: [I; 0, 8, -2 ], state: 6 }, { pos: [I; -1, 6, -3 ], state: 0 }, { pos: [I; -1, 8, -2 ], state: 6 }, { pos: [I; -2, 6, -3 ], state: 0 }, { pos: [I; -3, 6, -3 ], state: 0 }, { pos: [I; -4, 6, -3 ], state: 13 }, { pos: [I; 4, 5, -3 ], state: 18 }, { pos: [I; 3, 5, -3 ], state: 9 }, { pos: [I; 3, 7, -2 ], state: 6 }, { pos: [I; 2, 5, -3 ], state: 9 }, { pos: [I; 2, 7, -2 ], state: 8 }, { pos: [I; 1, 5, -3 ], state: 0 }, { pos: [I; 0, 5, -3 ], state: 9 }, { pos: [I; -1, 5, -3 ], state: 0 }, { pos: [I; -2, 5, -3 ], state: 9 }, { pos: [I; -2, 7, -2 ], state: 8 }, { pos: [I; -3, 5, -3 ], state: 9 }, { pos: [I; -3, 7, -2 ], state: 6 }, { pos: [I; -4, 5, -3 ], state: 16 }, { pos: [I; 4, 6, -2 ], state: 2 }, { pos: [I; 3, 4, -3 ], state: 4 }, { pos: [I; 2, 4, -3 ], state: 27 }, { nbt: { back_text: { color: "black", has_glowing_text: 0b, messages: [ "\"\"", "\"\"", "\"\"", "\"\"" ] }, front_text: { color: "black", has_glowing_text: 0b, messages: [ "\"\"", "\"\"", "\"\"", "\"\"" ] }, is_waxed: 0b }, pos: [I; 1, 2, -4 ], state: 28 }, { pos: [I; 1, 4, -3 ], state: 4 }, { pos: [I; 0, 4, -3 ], state: 27 }, { pos: [I; 1, 8, -1 ], state: 6 }, { pos: [I; -1, 4, -3 ], state: 4 }, { pos: [I; 0, 8, -1 ], state: 6 }, { pos: [I; -2, 4, -3 ], state: 27 }, { pos: [I; -1, 8, -1 ], state: 6 }, { pos: [I; -3, 4, -3 ], state: 4 }, { pos: [I; -4, 6, -2 ], state: 13 }, { pos: [I; 4, 5, -2 ], state: 7 }, { pos: [I; 3, 3, -3 ], state: 4 }, { pos: [I; 3, 5, -2 ], state: 9 }, { pos: [I; 2, 3, -3 ], state: 27 }, { pos: [I; 3, 7, -1 ], state: 6 }, { pos: [I; 2, 5, -2 ], state: 1 }, { pos: [I; 1, 3, -3 ], state: 4 }, { pos: [I; 2, 7, -1 ], state: 8 }, { pos: [I; 1, 5, -2 ], state: 1 }, { pos: [I; 0, 3, -3 ], state: 27 }, { pos: [I; 0, 5, -2 ], state: 1 }, { pos: [I; -1, 3, -3 ], state: 4 }, { pos: [I; -1, 5, -2 ], state: 1 }, { pos: [I; -2, 3, -3 ], state: 27 }, { pos: [I; -2, 5, -2 ], state: 1 }, { pos: [I; -3, 3, -3 ], state: 4 }, { pos: [I; -2, 7, -1 ], state: 8 }, { pos: [I; -3, 5, -2 ], state: 9 }, { pos: [I; -3, 7, -1 ], state: 6 }, { pos: [I; -4, 5, -2 ], state: 7 }, { pos: [I; 4, 0, -4 ], state: 5 }, { pos: [I; -4, 0, 4 ], state: 5 }, { pos: [I; 3, 0, -4 ], state: 5 }, { pos: [I; 3, 2, -3 ], state: 4 }, { pos: [I; -3, 0, 4 ], state: 5 }, { pos: [I; 2, 0, -4 ], state: 5 }, { pos: [I; 4, 6, -1 ], state: 2 }, { pos: [I; 3, 4, -2 ], state: 3 }, { pos: [I; 2, 2, -3 ], state: 27 }, { pos: [I; -2, 0, 4 ], state: 5 }, { pos: [I; 1, 0, -4 ], state: 5 }, { pos: [I; 1, 2, -3 ], state: 4 }, { pos: [I; -1, 0, 4 ], state: 5 }, { pos: [I; 0, 0, -4 ], state: 5 }, { pos: [I; 0, 2, -3 ], state: 29 }, { pos: [I; 0, 0, 4 ], state: 5 }, { pos: [I; -1, 0, -4 ], state: 5 }, { pos: [I; -1, 2, -3 ], state: 4 }, { pos: [I; 1, 0, 4 ], state: 5 }, { pos: [I; -2, 0, -4 ], state: 5 }, { pos: [I; -2, 2, -3 ], state: 27 }, { pos: [I; 2, 0, 4 ], state: 5 }, { pos: [I; -3, 0, -4 ], state: 5 }, { nbt: { Items: [ ] }, pos: [I; -2, 4, -2 ], state: 30 }, { pos: [I; -3, 2, -3 ], state: 4 }, { pos: [I; 3, 0, 4 ], state: 5 }, { pos: [I; -4, 0, -4 ], state: 5 }, { pos: [I; -3, 4, -2 ], state: 11 }, { pos: [I; 4, 0, 4 ], state: 5 }, { pos: [I; -4, 6, -1 ], state: 13 }, { pos: [I; 3, 1, -3 ], state: 4 }, { pos: [I; 4, 5, -1 ], state: 18 }, { pos: [I; 3, 3, -2 ], state: 3 }, { pos: [I; 2, 1, -3 ], state: 27 }, { pos: [I; 3, 5, -1 ], state: 9 }, { pos: [I; 1, 1, -3 ], state: 4 }, { pos: [I; 2, 5, -1 ], state: 1 }, { pos: [I; 0, 1, -3 ], state: 31 }, { pos: [I; 1, 5, -1 ], state: 1 }, { pos: [I; -1, 1, -3 ], state: 4 }, { pos: [I; 0, 5, -1 ], state: 1 }, { pos: [I; -2, 1, -3 ], state: 27 }, { pos: [I; -1, 5, -1 ], state: 1 }, { nbt: { Items: [ ] }, pos: [I; -2, 3, -2 ], state: 32 }, { pos: [I; -3, 1, -3 ], state: 4 }, { pos: [I; -2, 5, -1 ], state: 1 }, { pos: [I; -3, 3, -2 ], state: 11 }, { pos: [I; -3, 5, -1 ], state: 9 }, { pos: [I; -4, 5, -1 ], state: 16 }, { pos: [I; 4, 0, -3 ], state: 5 }, { pos: [I; -4, 0, 3 ], state: 5 }, { pos: [I; 3, 0, -3 ], state: 33 }, { pos: [I; 3, 2, -2 ], state: 3 }, { pos: [I; -3, 0, 3 ], state: 33 }, { pos: [I; 2, 0, -3 ], state: 5 }, { pos: [I; 3, 4, -1 ], state: 4 }, { nbt: { Container: { }, CookTime: 0, CookTimeTotal: 0, Inventory: { Items: [ ], Size: 9 }, RecipesUsed: { } }, pos: [I; 2, 2, -2 ], state: 34 }, { pos: [I; -2, 0, 3 ], state: 5 }, { pos: [I; 1, 0, -3 ], state: 33 }, { pos: [I; -1, 0, 3 ], state: 33 }, { pos: [I; 0, 0, -3 ], state: 5 }, { pos: [I; 0, 0, 3 ], state: 5 }, { pos: [I; -1, 0, -3 ], state: 33 }, { pos: [I; 1, 0, 3 ], state: 33 }, { pos: [I; -2, 0, -3 ], state: 5 }, { nbt: { Items: [ ] }, pos: [I; -2, 2, -2 ], state: 32 }, { pos: [I; 2, 0, 3 ], state: 5 }, { pos: [I; -3, 0, -3 ], state: 33 }, { nbt: { Items: [ ] }, pos: [I; -2, 4, -1 ], state: 35 }, { pos: [I; -3, 2, -2 ], state: 11 }, { pos: [I; 3, 0, 3 ], state: 33 }, { pos: [I; -4, 0, -3 ], state: 5 }, { pos: [I; -3, 4, -1 ], state: 4 }, { pos: [I; 4, 0, 3 ], state: 5 }, { pos: [I; 3, 1, -2 ], state: 3 }, { pos: [I; -3, 1, 3 ], state: 4 }, { pos: [I; 3, 3, -1 ], state: 4 }, { pos: [I; -2, 1, 3 ], state: 36 }, { nbt: { CookingTimes: [I; 0, 0, 0, 0, 0, 0 ], CookingTotalTimes: [I; 0, 0, 0, 0, 0, 0 ], Inventory: { Items: [ ], Size: 6 } }, pos: [I; 2, 1, -2 ], state: 37 }, { nbt: { Items: [ ] }, pos: [I; 2, 3, -1 ], state: 38 }, { pos: [I; -1, 1, 3 ], state: 4 }, { pos: [I; 0, 1, 3 ], state: 36 }, { pos: [I; 1, 1, 3 ], state: 4 }, { pos: [I; 2, 1, 3 ], state: 36 }, { nbt: { Items: [ ] }, pos: [I; -2, 1, -2 ], state: 39 }, { nbt: { Items: [ ] }, pos: [I; -2, 3, -1 ], state: 35 }, { pos: [I; -3, 1, -2 ], state: 11 }, { pos: [I; 3, 1, 3 ], state: 4 }, { pos: [I; -3, 3, -1 ], state: 4 }, { pos: [I; 4, 0, -2 ], state: 5 }, { pos: [I; -3, 2, 3 ], state: 4 }, { pos: [I; -4, 0, 2 ], state: 5 }, { pos: [I; 3, 0, -2 ], state: 5 }, { pos: [I; -1, 4, 4 ], state: 40 }, { pos: [I; -2, 2, 3 ], state: 36 }, { pos: [I; 3, 2, -1 ], state: 4 }, { pos: [I; -3, 0, 2 ], state: 5 }, { pos: [I; 2, 0, -2 ], state: 1 }, { pos: [I; -1, 2, 3 ], state: 4 }, { nbt: { Inventory: { Items: [ ], Size: 1 }, IsItemCarved: 0b }, pos: [I; 2, 2, -1 ], state: 41 }, { pos: [I; -2, 0, 2 ], state: 1 }, { pos: [I; 1, 0, -2 ], state: 1 }, { pos: [I; 1, 4, 4 ], state: 40 }, { pos: [I; 0, 2, 3 ], state: 15 }, { pos: [I; -1, 0, 2 ], state: 1 }, { pos: [I; 0, 0, -2 ], state: 1 }, { pos: [I; 1, 2, 3 ], state: 4 }, { pos: [I; 0, 0, 2 ], state: 1 }, { pos: [I; -1, 0, -2 ], state: 1 }, { pos: [I; 2, 2, 3 ], state: 36 }, { pos: [I; 1, 0, 2 ], state: 1 }, { pos: [I; -2, 0, -2 ], state: 1 }, { pos: [I; 3, 2, 3 ], state: 4 }, { nbt: { Items: [ ] }, pos: [I; -2, 2, -1 ], state: 35 }, { pos: [I; 2, 0, 2 ], state: 1 }, { pos: [I; -3, 0, -2 ], state: 5 }, { pos: [I; -3, 2, -1 ], state: 4 }, { pos: [I; 3, 0, 2 ], state: 5 }, { pos: [I; -4, 0, -2 ], state: 5 }, { pos: [I; 4, 0, 2 ], state: 5 }, { pos: [I; -4, 5, 4 ], state: 7 }, { pos: [I; -2, 5, 4 ], state: 42 }, { pos: [I; -3, 3, 3 ], state: 4 }, { pos: [I; -1, 5, 4 ], state: 42 }, { pos: [I; -2, 3, 3 ], state: 36 }, { pos: [I; -3, 1, 2 ], state: 11 }, { pos: [I; 3, 1, -1 ], state: 4 }, { pos: [I; -1, 3, 3 ], state: 4 }, { pos: [I; -2, 1, 2 ], state: 43 }, { nbt: { Items: [ ] }, pos: [I; 2, 1, -1 ], state: 38 }, { pos: [I; 1, 5, 4 ], state: 42 }, { pos: [I; 0, 3, 3 ], state: 19 }, { pos: [I; 2, 5, 4 ], state: 42 }, { pos: [I; 1, 3, 3 ], state: 4 }, { pos: [I; 2, 3, 3 ], state: 36 }, { pos: [I; 1, 1, 2 ], state: 44 }, { pos: [I; 4, 5, 4 ], state: 7 }, { pos: [I; 3, 3, 3 ], state: 4 }, { pos: [I; 2, 1, 2 ], state: 45 }, { nbt: { Items: [ ] }, pos: [I; -2, 1, -1 ], state: 35 }, { pos: [I; 3, 1, 2 ], state: 3 }, { pos: [I; -3, 1, -1 ], state: 4 }, { pos: [I; -4, 6, 4 ], state: 23 }, { pos: [I; -3, 6, 4 ], state: 18 }, { pos: [I; -2, 6, 4 ], state: 7 }, { pos: [I; -3, 4, 3 ], state: 4 }, { pos: [I; 4, 0, -1 ], state: 5 }, { pos: [I; -2, 4, 3 ], state: 36 }, { pos: [I; -3, 2, 2 ], state: 11 }, { pos: [I; -4, 0, 1 ], state: 5 }, { pos: [I; 3, 0, -1 ], state: 33 }, { pos: [I; -1, 4, 3 ], state: 4 }, { pos: [I; -2, 2, 2 ], state: 19 }, { pos: [I; -3, 0, 1 ], state: 33 }, { pos: [I; 2, 0, -1 ], state: 1 }, { pos: [I; 0, 4, 3 ], state: 36 }, { pos: [I; -2, 0, 1 ], state: 1 }, { pos: [I; 1, 0, -1 ], state: 1 }, { pos: [I; 2, 6, 4 ], state: 7 }, { pos: [I; 1, 4, 3 ], state: 4 }, { pos: [I; -1, 0, 1 ], state: 1 }, { pos: [I; 0, 0, -1 ], state: 1 }, { pos: [I; 3, 6, 4 ], state: 16 }, { pos: [I; 2, 4, 3 ], state: 36 }, { pos: [I; 0, 0, 1 ], state: 1 }, { pos: [I; -1, 0, -1 ], state: 1 }, { pos: [I; 4, 6, 4 ], state: 22 }, { pos: [I; 3, 4, 3 ], state: 4 }, { pos: [I; 1, 0, 1 ], state: 1 }, { pos: [I; -2, 0, -1 ], state: 1 }, { pos: [I; 3, 2, 2 ], state: 3 }, { pos: [I; 2, 0, 1 ], state: 1 }, { pos: [I; -3, 0, -1 ], state: 33 }, { pos: [I; 3, 0, 1 ], state: 33 }, { pos: [I; -4, 0, -1 ], state: 5 }, { pos: [I; 4, 0, 1 ], state: 5 }, { pos: [I; -3, 7, 4 ], state: 21 }, { pos: [I; -4, 5, 3 ], state: 16 }, { pos: [I; -2, 7, 4 ], state: 9 }, { pos: [I; -3, 5, 3 ], state: 9 }, { pos: [I; -1, 7, 4 ], state: 9 }, { pos: [I; -2, 5, 3 ], state: 9 }, { pos: [I; -3, 3, 2 ], state: 11 }, { pos: [I; 0, 7, 4 ], state: 7 }, { pos: [I; -1, 5, 3 ], state: 9 }, { pos: [I; -2, 3, 2 ], state: 46 }, { pos: [I; -3, 1, 1 ], state: 4 }, { pos: [I; 1, 7, 4 ], state: 9 }, { pos: [I; 0, 5, 3 ], state: 9 }, { pos: [I; 2, 7, 4 ], state: 9 }, { pos: [I; 1, 5, 3 ], state: 9 }, { nbt: { camo: { type: "framedblocks:empty" }, glowing: 0b, intangible: 0b, reinforced: 0b, updated: 3b }, pos: [I; -1, 1, 1 ], state: 47 }, { pos: [I; 3, 7, 4 ], state: 21 }, { pos: [I; 2, 5, 3 ], state: 9 }, { pos: [I; 3, 5, 3 ], state: 9 }, { pos: [I; 4, 5, 3 ], state: 18 }, { pos: [I; 3, 3, 2 ], state: 3 }, { pos: [I; 3, 1, 1 ], state: 4 }, { pos: [I; -4, 6, 3 ], state: 13 }, { pos: [I; -3, 6, 3 ], state: 0 }, { pos: [I; -1, 8, 4 ], state: 21 }, { pos: [I; -2, 6, 3 ], state: 0 }, { pos: [I; -3, 4, 2 ], state: 11 }, { pos: [I; 0, 8, 4 ], state: 21 }, { pos: [I; -1, 6, 3 ], state: 0 }, { pos: [I; -3, 2, 1 ], state: 4 }, { pos: [I; 1, 8, 4 ], state: 21 }, { pos: [I; 0, 6, 3 ], state: 0 }, { pos: [I; -2, 2, 1 ], state: 19 }, { pos: [I; 1, 6, 3 ], state: 0 }, { nbt: { camo: { type: "framedblocks:empty" }, glowing: 0b, intangible: 0b, reinforced: 0b, updated: 3b }, pos: [I; -1, 2, 1 ], state: 47 }, { pos: [I; 2, 6, 3 ], state: 0 } ], states: [ { Name: "minecraft:stripped_bamboo_block", Properties: { axis: "y" } }, { Name: "chipped:oak_planks_mosaic" }, { Name: "minecraft:bamboo_stairs", Properties: { facing: "west", half: "bottom", shape: "straight", waterlogged: "false" } }, { Name: "chipped:heavy_bamboo_trapdoor", Properties: { facing: "east", half: "bottom", open: "true", powered: "false", waterlogged: "false" } }, { Name: "chipped:edged_stripped_spruce_log", Properties: { axis: "y" } }, { Name: "minecraft:grass_block", Properties: { snowy: "false" } }, { Name: "minecraft:bamboo_slab", Properties: { type: "bottom", waterlogged: "false" } }, { Name: "minecraft:spruce_slab", Properties: { type: "top", waterlogged: "false" } }, { Name: "minecraft:bamboo_slab", Properties: { type: "top", waterlogged: "false" } }, { Name: "minecraft:spruce_slab", Properties: { type: "double", waterlogged: "false" } }, { Name: "handcrafted:bamboo_fancy_bed", Properties: { color: "white", facing: "south", occupied: "false", part: "foot", shape: "single" } }, { Name: "chipped:heavy_bamboo_trapdoor", Properties: { facing: "west", half: "bottom", open: "true", powered: "false", waterlogged: "false" } }, { Name: "farmersdelight:basket", Properties: { enabled: "true", facing: "up", waterlogged: "false" } }, { Name: "minecraft:bamboo_stairs", Properties: { facing: "east", half: "bottom", shape: "straight", waterlogged: "false" } }, { Name: "chipped:heavy_bamboo_trapdoor", Properties: { facing: "south", half: "bottom", open: "false", powered: "false", waterlogged: "false" } }, { Name: "chipped:heavy_bamboo_trapdoor", Properties: { facing: "east", half: "bottom", open: "false", powered: "false", waterlogged: "false" } }, { Name: "minecraft:spruce_stairs", Properties: { facing: "east", half: "top", shape: "straight", waterlogged: "false" } }, { Name: "chipped:heavy_bamboo_trapdoor", Properties: { facing: "south", half: "top", open: "false", powered: "false", waterlogged: "false" } }, { Name: "minecraft:spruce_stairs", Properties: { facing: "west", half: "top", shape: "straight", waterlogged: "false" } }, { Name: "chipped:heavy_bamboo_trapdoor", Properties: { facing: "east", half: "top", open: "false", powered: "false", waterlogged: "false" } }, { Name: "mcwlights:golden_small_chandelier", Properties: { lit: "true" } }, { Name: "minecraft:spruce_slab", Properties: { type: "bottom", waterlogged: "false" } }, { Name: "minecraft:spruce_stairs", Properties: { facing: "west", half: "bottom", shape: "straight", waterlogged: "false" } }, { Name: "minecraft:spruce_stairs", Properties: { facing: "east", half: "bottom", shape: "straight", waterlogged: "false" } }, { Name: "minecraft:spruce_trapdoor", Properties: { facing: "north", half: "bottom", open: "true", powered: "false", waterlogged: "false" } }, { Name: "minecraft:bamboo_slab", Properties: { type: "double", waterlogged: "false" } }, { Name: "minecraft:spruce_trapdoor", Properties: { facing: "north", half: "top", open: "true", powered: "false", waterlogged: "false" } }, { Name: "chipped:heavy_bamboo_trapdoor", Properties: { facing: "north", half: "bottom", open: "true", powered: "false", waterlogged: "false" } }, { Name: "farmersdelight:yellow_wall_hanging_canvas_sign", Properties: { facing: "west", waterlogged: "false" } }, { Name: "chipped:boarded_bamboo_door", Properties: { facing: "north", half: "upper", hinge: "right", open: "false", powered: "false" } }, { Name: "mcwfurnitures:stripped_jungle_bookshelf", Properties: { connection: "top", facing: "north" } }, { Name: "chipped:boarded_bamboo_door", Properties: { facing: "north", half: "lower", hinge: "right", open: "false", powered: "false" } }, { Name: "mcwfurnitures:stripped_jungle_bookshelf", Properties: { connection: "middle", facing: "north" } }, { Name: "minecraft:dirt" }, { Name: "farmersdelight:cooking_pot", Properties: { facing: "east", support: "none", waterlogged: "false" } }, { Name: "handcrafted:bamboo_shelf", Properties: { facing: "east", shape: "single", type: "1" } }, { Name: "chipped:heavy_bamboo_trapdoor", Properties: { facing: "south", half: "bottom", open: "true", powered: "false", waterlogged: "false" } }, { Name: "farmersdelight:stove", Properties: { facing: "west", lit: "true" } }, { Name: "farmersdelight:bamboo_cabinet", Properties: { facing: "west", open: "false" } }, { Name: "mcwfurnitures:stripped_jungle_bookshelf", Properties: { connection: "bottom", facing: "north" } }, { Name: "minecraft:spruce_trapdoor", Properties: { facing: "south", half: "top", open: "true", powered: "false", waterlogged: "false" } }, { Name: "farmersdelight:cutting_board", Properties: { facing: "west", waterlogged: "false" } }, { Name: "minecraft:spruce_trapdoor", Properties: { facing: "south", half: "bottom", open: "true", powered: "false", waterlogged: "false" } }, { Name: "handcrafted:white_glazed_thick_pot" }, { Name: "handcrafted:bamboo_chair", Properties: { color: "none", facing: "east", waterlogged: "false" } }, { Name: "handcrafted:bamboo_table", Properties: { color: "none", shape: "single", waterlogged: "false" } }, { Name: "handcrafted:bamboo_fancy_bed", Properties: { color: "white", facing: "south", occupied: "false", part: "head", shape: "single" } }, { Name: "framedblocks:framed_ladder", Properties: { facing: "west", glowing: "false", propagates_skylight: "false", waterlogged: "false" } } ] }, "minecraft:custom_name": "\"House #1\"", "minecraft:dyed_color": { rgb: 11546150 } }, count: 1, id: "bagofyurting:bag_of_yurting" } }
		{ id: "3A94B346DECCD345", item: { components: { "bagofyurting:radius": 4, "bagofyurting:yurtdata": { data: [ { pos: [I; 2, 4, 2 ], state: 0 }, { pos: [I; -1, 0, 0 ], state: 1 }, { pos: [I; 0, 0, 0 ], state: 1 }, { pos: [I; 3, 4, 2 ], state: 2 }, { nbt: { Items: [ ] }, pos: [I; 2, 2, 1 ], state: 3 }, { pos: [I; -2, 0, 0 ], state: 1 }, { pos: [I; 1, 0, 0 ], state: 1 }, { pos: [I; 3, 2, 1 ], state: 2 }, { pos: [I; -3, 0, 0 ], state: 4 }, { pos: [I; 2, 0, 0 ], state: 4 }, { pos: [I; 4, 2, 1 ], state: 5 }, { pos: [I; -4, 0, 0 ], state: 6 }, { pos: [I; 3, 0, 0 ], state: 4 }, { pos: [I; 4, 0, 0 ], state: 6 }, { pos: [I; -4, 3, 1 ], state: 7 }, { pos: [I; -2, 5, 2 ], state: 8 }, { pos: [I; -3, 3, 1 ], state: 2 }, { pos: [I; -4, 1, 0 ], state: 7 }, { pos: [I; -1, 5, 2 ], state: 2 }, { pos: [I; -2, 3, 1 ], state: 2 }, { pos: [I; -3, 1, 0 ], state: 2 }, { pos: [I; 0, 5, 2 ], state: 1 }, { pos: [I; -1, 3, 1 ], state: 2 }, { nbt: { CookingTimes: [I; 0, 0, 0, 0, 0, 0 ], CookingTotalTimes: [I; 0, 0, 0, 0, 0, 0 ], Inventory: { Items: [ ], Size: 6 } }, pos: [I; -2, 1, 0 ], state: 9 }, { pos: [I; 1, 5, 2 ], state: 1 }, { nbt: { Items: [ ] }, pos: [I; 0, 3, 1 ], state: 10 }, { nbt: { Items: [ ] }, pos: [I; -1, 1, 0 ], state: 11 }, { pos: [I; 2, 5, 2 ], state: 1 }, { pos: [I; 0, 1, 0 ], state: 12 }, { pos: [I; 3, 5, 2 ], state: 2 }, { nbt: { Items: [ ] }, pos: [I; 2, 3, 1 ], state: 3 }, { pos: [I; 4, 5, 2 ], state: 8 }, { pos: [I; 3, 3, 1 ], state: 2 }, { pos: [I; 2, 1, 0 ], state: 2 }, { pos: [I; 4, 3, 1 ], state: 5 }, { pos: [I; 3, 1, 0 ], state: 2 }, { pos: [I; 4, 1, 0 ], state: 13 }, { pos: [I; -4, 4, 1 ], state: 8 }, { pos: [I; -2, 6, 2 ], state: 14 }, { pos: [I; -3, 4, 1 ], state: 2 }, { pos: [I; -4, 2, 0 ], state: 7 }, { pos: [I; -1, 6, 2 ], state: 15 }, { pos: [I; -2, 4, 1 ], state: 2 }, { pos: [I; -3, 2, 0 ], state: 2 }, { pos: [I; 0, 6, 2 ], state: 16 }, { pos: [I; -1, 4, 1 ], state: 2 }, { nbt: { Container: { }, CookTime: 0, CookTimeTotal: 0, Inventory: { Items: [ ], Size: 9 }, RecipesUsed: { } }, pos: [I; -2, 2, 0 ], state: 17 }, { pos: [I; 1, 6, 2 ], state: 16 }, { nbt: { Items: [ ] }, pos: [I; 0, 4, 1 ], state: 10 }, { pos: [I; 2, 6, 2 ], state: 16 }, { pos: [I; 0, 2, 0 ], state: 12 }, { pos: [I; 3, 6, 2 ], state: 15 }, { nbt: { Items: [ ] }, pos: [I; 2, 4, 1 ], state: 3 }, { pos: [I; 4, 6, 2 ], state: 14 }, { pos: [I; 3, 4, 1 ], state: 2 }, { pos: [I; 2, 2, 0 ], state: 2 }, { pos: [I; 4, 4, 1 ], state: 5 }, { pos: [I; 3, 2, 0 ], state: 2 }, { pos: [I; 4, 2, 0 ], state: 13 }, { pos: [I; -4, 5, 1 ], state: 14 }, { pos: [I; -3, 5, 1 ], state: 14 }, { pos: [I; -2, 5, 1 ], state: 18 }, { pos: [I; -3, 3, 0 ], state: 2 }, { pos: [I; -1, 5, 1 ], state: 2 }, { pos: [I; 0, 5, 1 ], state: 1 }, { pos: [I; 1, 5, 1 ], state: 1 }, { pos: [I; 0, 3, 0 ], state: 12 }, { pos: [I; 2, 5, 1 ], state: 1 }, { pos: [I; 3, 5, 1 ], state: 2 }, { pos: [I; 2, 3, 0 ], state: 2 }, { pos: [I; 4, 5, 1 ], state: 18 }, { pos: [I; 3, 3, 0 ], state: 2 }, { pos: [I; 4, 3, 0 ], state: 5 }, { pos: [I; -2, 6, 1 ], state: 19 }, { pos: [I; -3, 4, 0 ], state: 2 }, { pos: [I; -1, 6, 1 ], state: 20 }, { nbt: { CookingTimes: [I; 0, 0, 0, 0, 0, 0 ], CookingTotalTimes: [I; 0, 0, 0, 0, 0, 0 ], Inventory: { Items: [ ], Size: 6 } }, pos: [I; -2, 4, 0 ], state: 21 }, { pos: [I; 0, 4, 0 ], state: 12 }, { pos: [I; 2, 6, 1 ], state: 22 }, { pos: [I; 3, 6, 1 ], state: 23 }, { pos: [I; 2, 4, 0 ], state: 2 }, { pos: [I; 4, 6, 1 ], state: 19 }, { pos: [I; 3, 4, 0 ], state: 2 }, { pos: [I; 4, 4, 0 ], state: 18 }, { pos: [I; -4, 5, 0 ], state: 8 }, { pos: [I; -3, 5, 0 ], state: 2 }, { pos: [I; -2, 5, 0 ], state: 1 }, { pos: [I; 0, 7, 1 ], state: 24 }, { pos: [I; -1, 5, 0 ], state: 1 }, { pos: [I; 1, 7, 1 ], state: 24 }, { pos: [I; 0, 5, 0 ], state: 1 }, { pos: [I; 1, 5, 0 ], state: 1 }, { pos: [I; 3, 5, 0 ], state: 22 }, { pos: [I; 4, 5, 0 ], state: 19 }, { pos: [I; -4, 6, 0 ], state: 14 }, { pos: [I; -3, 6, 0 ], state: 2 }, { pos: [I; -2, 6, 0 ], state: 15 }, { pos: [I; -1, 6, 0 ], state: 16 }, { pos: [I; 2, 6, 0 ], state: 16 }, { pos: [I; -3, 7, 0 ], state: 25 }, { pos: [I; -1, 7, 0 ], state: 24 }, { pos: [I; 0, 7, 0 ], state: 24 }, { pos: [I; 1, 7, 0 ], state: 24 }, { pos: [I; -3, 8, 0 ], state: 26 }, { pos: [I; 3, 4, -4 ], state: 19 }, { pos: [I; 2, 4, -4 ], state: 19 }, { pos: [I; 1, 4, -4 ], state: 19 }, { pos: [I; 0, 4, -4 ], state: 19 }, { pos: [I; 0, 6, -3 ], state: 23 }, { pos: [I; -1, 4, -4 ], state: 19 }, { pos: [I; -1, 6, -3 ], state: 23 }, { pos: [I; -2, 4, -4 ], state: 19 }, { pos: [I; -3, 4, -4 ], state: 19 }, { pos: [I; -4, 4, -4 ], state: 19 }, { pos: [I; 3, 3, -4 ], state: 27 }, { pos: [I; 3, 5, -3 ], state: 19 }, { pos: [I; 2, 5, -3 ], state: 23 }, { pos: [I; 1, 3, -4 ], state: 28 }, { pos: [I; 1, 5, -3 ], state: 23 }, { pos: [I; 0, 5, -3 ], state: 16 }, { pos: [I; 0, 7, -2 ], state: 24 }, { pos: [I; -1, 5, -3 ], state: 16 }, { pos: [I; -2, 3, -4 ], state: 28 }, { pos: [I; -1, 7, -2 ], state: 24 }, { pos: [I; -2, 5, -3 ], state: 23 }, { pos: [I; -3, 3, -4 ], state: 29 }, { pos: [I; -3, 5, -3 ], state: 23 }, { pos: [I; -4, 3, -4 ], state: 27 }, { pos: [I; -4, 5, -3 ], state: 19 }, { pos: [I; 3, 2, -4 ], state: 30 }, { pos: [I; 3, 4, -3 ], state: 18 }, { pos: [I; 2, 2, -4 ], state: 29 }, { pos: [I; 3, 6, -2 ], state: 19 }, { pos: [I; 2, 4, -3 ], state: 2 }, { pos: [I; 1, 2, -4 ], state: 13 }, { pos: [I; 2, 6, -2 ], state: 23 }, { pos: [I; 1, 4, -3 ], state: 2 }, { pos: [I; 1, 6, -2 ], state: 16 }, { pos: [I; 0, 4, -3 ], state: 2 }, { pos: [I; 0, 6, -2 ], state: 16 }, { pos: [I; -1, 4, -3 ], state: 2 }, { pos: [I; -2, 2, -4 ], state: 29 }, { pos: [I; -1, 6, -2 ], state: 16 }, { pos: [I; -2, 4, -3 ], state: 2 }, { pos: [I; -3, 2, -4 ], state: 13 }, { pos: [I; -2, 6, -2 ], state: 16 }, { pos: [I; -3, 4, -3 ], state: 2 }, { pos: [I; -4, 2, -4 ], state: 30 }, { pos: [I; -3, 6, -2 ], state: 23 }, { pos: [I; -4, 4, -3 ], state: 18 }, { pos: [I; -4, 6, -2 ], state: 19 }, { pos: [I; 3, 1, -4 ], state: 27 }, { pos: [I; 2, 1, -4 ], state: 13 }, { pos: [I; 3, 5, -2 ], state: 18 }, { pos: [I; 2, 3, -3 ], state: 2 }, { pos: [I; 1, 1, -4 ], state: 13 }, { pos: [I; 2, 5, -2 ], state: 2 }, { pos: [I; 1, 3, -3 ], state: 2 }, { pos: [I; 0, 1, -4 ], state: 29 }, { pos: [I; 1, 5, -2 ], state: 1 }, { pos: [I; 0, 3, -3 ], state: 31 }, { pos: [I; 1, 7, -1 ], state: 24 }, { pos: [I; 0, 5, -2 ], state: 1 }, { pos: [I; -1, 3, -3 ], state: 31 }, { pos: [I; -2, 1, -4 ], state: 13 }, { pos: [I; 0, 7, -1 ], state: 24 }, { pos: [I; -1, 5, -2 ], state: 1 }, { pos: [I; -2, 3, -3 ], state: 2 }, { pos: [I; -3, 1, -4 ], state: 13 }, { pos: [I; -1, 7, -1 ], state: 24 }, { pos: [I; -2, 5, -2 ], state: 1 }, { pos: [I; -3, 3, -3 ], state: 2 }, { pos: [I; -4, 1, -4 ], state: 27 }, { pos: [I; -2, 7, -1 ], state: 24 }, { pos: [I; -3, 5, -2 ], state: 2 }, { pos: [I; -3, 7, -1 ], state: 24 }, { pos: [I; -4, 5, -2 ], state: 18 }, { pos: [I; -4, 7, -1 ], state: 32 }, { pos: [I; 4, 0, -4 ], state: 6 }, { pos: [I; 3, 0, -4 ], state: 6 }, { pos: [I; -4, 0, 4 ], state: 6 }, { pos: [I; 2, 0, -4 ], state: 6 }, { pos: [I; -3, 0, 4 ], state: 6 }, { pos: [I; 2, 2, -3 ], state: 2 }, { pos: [I; 1, 0, -4 ], state: 6 }, { pos: [I; -2, 0, 4 ], state: 6 }, { pos: [I; 3, 6, -1 ], state: 14 }, { pos: [I; 2, 4, -2 ], state: 2 }, { pos: [I; 1, 2, -3 ], state: 2 }, { pos: [I; 0, 0, -4 ], state: 6 }, { pos: [I; -1, 0, 4 ], state: 6 }, { pos: [I; 2, 6, -1 ], state: 33 }, { pos: [I; 0, 2, -3 ], state: 31 }, { pos: [I; -1, 0, -4 ], state: 6 }, { pos: [I; 0, 0, 4 ], state: 6 }, { pos: [I; -1, 2, -3 ], state: 31 }, { pos: [I; -2, 0, -4 ], state: 6 }, { pos: [I; 1, 0, 4 ], state: 6 }, { pos: [I; -2, 2, -3 ], state: 2 }, { pos: [I; -3, 0, -4 ], state: 6 }, { pos: [I; 2, 0, 4 ], state: 6 }, { pos: [I; -3, 2, -3 ], state: 2 }, { pos: [I; -4, 0, -4 ], state: 6 }, { pos: [I; 3, 0, 4 ], state: 6 }, { pos: [I; -3, 4, -2 ], state: 2 }, { pos: [I; -4, 2, -3 ], state: 7 }, { pos: [I; 4, 0, 4 ], state: 6 }, { pos: [I; -4, 6, -1 ], state: 34 }, { pos: [I; 2, 1, -3 ], state: 2 }, { pos: [I; -2, 1, 4 ], state: 27 }, { pos: [I; 3, 5, -1 ], state: 8 }, { pos: [I; 2, 3, -2 ], state: 2 }, { pos: [I; 1, 1, -3 ], state: 2 }, { pos: [I; 2, 5, -1 ], state: 2 }, { pos: [I; 0, 1, -3 ], state: 2 }, { pos: [I; 1, 5, -1 ], state: 1 }, { pos: [I; -1, 1, -3 ], state: 2 }, { pos: [I; 0, 5, -1 ], state: 1 }, { pos: [I; 2, 1, 4 ], state: 13 }, { pos: [I; -2, 1, -3 ], state: 2 }, { pos: [I; -1, 5, -1 ], state: 1 }, { nbt: { Items: [{ Slot: 0b, count: 1, id: "comforts:sleeping_bag_brown" }] }, pos: [I; -2, 3, -2 ], state: 35 }, { pos: [I; 3, 1, 4 ], state: 13 }, { pos: [I; -3, 1, -3 ], state: 2 }, { pos: [I; -2, 5, -1 ], state: 1 }, { pos: [I; -3, 3, -2 ], state: 2 }, { pos: [I; -4, 1, -3 ], state: 7 }, { pos: [I; 4, 1, 4 ], state: 27 }, { pos: [I; -3, 5, -1 ], state: 2 }, { pos: [I; 4, 0, -3 ], state: 6 }, { pos: [I; 3, 0, -3 ], state: 6 }, { pos: [I; -4, 0, 3 ], state: 6 }, { pos: [I; 4, 4, -1 ], state: 19 }, { pos: [I; -2, 2, 4 ], state: 30 }, { pos: [I; 2, 0, -3 ], state: 4 }, { pos: [I; -3, 0, 3 ], state: 6 }, { pos: [I; 2, 2, -2 ], state: 36 }, { pos: [I; 1, 0, -3 ], state: 4 }, { pos: [I; -2, 0, 3 ], state: 6 }, { pos: [I; 2, 4, -1 ], state: 2 }, { pos: [I; 0, 0, -3 ], state: 4 }, { pos: [I; -1, 0, 3 ], state: 4 }, { pos: [I; -1, 0, -3 ], state: 4 }, { pos: [I; 0, 0, 3 ], state: 4 }, { pos: [I; 0, 4, -1 ], state: 37 }, { pos: [I; -1, 2, -2 ], state: 38 }, { pos: [I; -2, 0, -3 ], state: 4 }, { pos: [I; 1, 0, 3 ], state: 4 }, { pos: [I; 3, 2, 4 ], state: 13 }, { pos: [I; -3, 0, -3 ], state: 4 }, { pos: [I; 2, 0, 3 ], state: 4 }, { pos: [I; -3, 2, -2 ], state: 2 }, { pos: [I; 4, 2, 4 ], state: 30 }, { pos: [I; -4, 0, -3 ], state: 6 }, { pos: [I; 3, 0, 3 ], state: 4 }, { pos: [I; -3, 4, -1 ], state: 39 }, { pos: [I; 4, 0, 3 ], state: 6 }, { pos: [I; 4, 3, -1 ], state: 27 }, { pos: [I; -2, 3, 4 ], state: 27 }, { pos: [I; -3, 1, 3 ], state: 40 }, { pos: [I; 3, 3, -1 ], state: 29 }, { pos: [I; 2, 1, -2 ], state: 41 }, { pos: [I; -2, 1, 3 ], state: 7 }, { pos: [I; 2, 3, -1 ], state: 2 }, { pos: [I; -1, 1, 3 ], state: 2 }, { pos: [I; 0, 1, 3 ], state: 2 }, { pos: [I; -1, 1, -2 ], state: 42 }, { pos: [I; 1, 1, 3 ], state: 2 }, { pos: [I; 3, 3, 4 ], state: 43 }, { pos: [I; -2, 1, -2 ], state: 44 }, { pos: [I; 2, 1, 3 ], state: 2 }, { pos: [I; 4, 3, 4 ], state: 27 }, { pos: [I; -3, 1, -2 ], state: 2 }, { pos: [I; 3, 1, 3 ], state: 2 }, { pos: [I; -3, 3, -1 ], state: 39 }, { pos: [I; -4, 1, -2 ], state: 7 }, { pos: [I; 4, 1, 3 ], state: 13 }, { pos: [I; 4, 0, -2 ], state: 6 }, { pos: [I; -2, 4, 4 ], state: 14 }, { pos: [I; -3, 2, 3 ], state: 40 }, { pos: [I; 4, 2, -1 ], state: 30 }, { pos: [I; 3, 0, -2 ], state: 6 }, { pos: [I; -4, 0, 2 ], state: 6 }, { pos: [I; -1, 4, 4 ], state: 14 }, { pos: [I; 3, 2, -1 ], state: 29 }, { pos: [I; -2, 2, 3 ], state: 7 }, { pos: [I; 2, 0, -2 ], state: 1 }, { pos: [I; -3, 0, 2 ], state: 6 }, { pos: [I; 0, 4, 4 ], state: 14 }, { pos: [I; 2, 2, -1 ], state: 2 }, { pos: [I; -1, 2, 3 ], state: 2 }, { pos: [I; 1, 0, -2 ], state: 1 }, { pos: [I; -2, 0, 2 ], state: 6 }, { pos: [I; 1, 4, 4 ], state: 14 }, { pos: [I; 0, 2, 3 ], state: 31 }, { pos: [I; 0, 0, -2 ], state: 1 }, { pos: [I; -1, 0, 2 ], state: 4 }, { pos: [I; 2, 4, 4 ], state: 14 }, { pos: [I; 1, 2, 3 ], state: 2 }, { pos: [I; -1, 0, -2 ], state: 1 }, { pos: [I; 0, 0, 2 ], state: 1 }, { pos: [I; 3, 4, 4 ], state: 14 }, { pos: [I; 2, 2, 3 ], state: 31 }, { pos: [I; -2, 0, -2 ], state: 1 }, { pos: [I; 1, 0, 2 ], state: 1 }, { pos: [I; 4, 4, 4 ], state: 14 }, { pos: [I; 3, 2, 3 ], state: 2 }, { pos: [I; -3, 0, -2 ], state: 4 }, { pos: [I; 2, 0, 2 ], state: 1 }, { pos: [I; -3, 2, -1 ], state: 39 }, { pos: [I; 4, 2, 3 ], state: 5 }, { pos: [I; -4, 0, -2 ], state: 6 }, { pos: [I; 3, 0, 2 ], state: 4 }, { pos: [I; 4, 0, 2 ], state: 6 }, { pos: [I; 4, 1, -1 ], state: 27 }, { pos: [I; -4, 1, 2 ], state: 27 }, { pos: [I; -2, 3, 3 ], state: 7 }, { pos: [I; 3, 1, -1 ], state: 13 }, { pos: [I; -3, 1, 2 ], state: 13 }, { pos: [I; -1, 3, 3 ], state: 2 }, { pos: [I; -2, 1, 2 ], state: 13 }, { pos: [I; 2, 1, -1 ], state: 2 }, { pos: [I; 0, 3, 3 ], state: 31 }, { pos: [I; -1, 1, 2 ], state: 2 }, { pos: [I; 1, 3, 3 ], state: 2 }, { nbt: { Items: [ ] }, pos: [I; 0, 1, 2 ], state: 45 }, { pos: [I; 2, 3, 3 ], state: 31 }, { pos: [I; 3, 3, 3 ], state: 2 }, { pos: [I; 2, 1, 2 ], state: 0 }, { pos: [I; 4, 3, 3 ], state: 5 }, { pos: [I; -3, 1, -1 ], state: 2 }, { pos: [I; 3, 1, 2 ], state: 2 }, { pos: [I; -4, 2, 2 ], state: 30 }, { pos: [I; 4, 0, -1 ], state: 6 }, { pos: [I; -2, 4, 3 ], state: 8 }, { pos: [I; -3, 2, 2 ], state: 13 }, { pos: [I; 3, 0, -1 ], state: 6 }, { pos: [I; -4, 0, 1 ], state: 6 }, { pos: [I; -1, 4, 3 ], state: 2 }, { pos: [I; -2, 2, 2 ], state: 13 }, { pos: [I; 2, 0, -1 ], state: 4 }, { pos: [I; -3, 0, 1 ], state: 4 }, { pos: [I; 0, 4, 3 ], state: 2 }, { pos: [I; -1, 2, 2 ], state: 2 }, { pos: [I; 1, 0, -1 ], state: 1 }, { pos: [I; -2, 0, 1 ], state: 4 }, { pos: [I; 1, 4, 3 ], state: 2 }, { nbt: { Items: [{ Slot: 0b, count: 1, id: "comforts:sleeping_bag_brown" }] }, pos: [I; 0, 2, 2 ], state: 35 }, { pos: [I; 0, 0, -1 ], state: 1 }, { pos: [I; -1, 0, 1 ], state: 4 }, { pos: [I; 2, 4, 3 ], state: 2 }, { pos: [I; -1, 0, -1 ], state: 1 }, { pos: [I; 0, 0, 1 ], state: 1 }, { pos: [I; 3, 4, 3 ], state: 2 }, { pos: [I; 2, 2, 2 ], state: 0 }, { pos: [I; -2, 0, -1 ], state: 1 }, { pos: [I; 1, 0, 1 ], state: 1 }, { pos: [I; 4, 4, 3 ], state: 8 }, { pos: [I; 3, 2, 2 ], state: 39 }, { pos: [I; -3, 0, -1 ], state: 4 }, { pos: [I; 2, 0, 1 ], state: 1 }, { pos: [I; -4, 0, -1 ], state: 6 }, { pos: [I; 3, 0, 1 ], state: 4 }, { pos: [I; 4, 0, 1 ], state: 6 }, { pos: [I; -4, 3, 2 ], state: 27 }, { pos: [I; -2, 5, 3 ], state: 14 }, { pos: [I; -3, 3, 2 ], state: 46 }, { pos: [I; -4, 1, 1 ], state: 7 }, { pos: [I; -1, 5, 3 ], state: 15 }, { pos: [I; -2, 3, 2 ], state: 13 }, { pos: [I; -3, 1, 1 ], state: 2 }, { pos: [I; 0, 5, 3 ], state: 15 }, { pos: [I; -1, 3, 2 ], state: 2 }, { pos: [I; -2, 1, 1 ], state: 2 }, { pos: [I; 1, 5, 3 ], state: 16 }, { pos: [I; -1, 1, 1 ], state: 2 }, { pos: [I; 2, 5, 3 ], state: 15 }, { nbt: { Items: [ ] }, pos: [I; 0, 1, 1 ], state: 10 }, { pos: [I; 3, 5, 3 ], state: 15 }, { pos: [I; 2, 3, 2 ], state: 0 }, { pos: [I; 4, 5, 3 ], state: 14 }, { pos: [I; 3, 3, 2 ], state: 39 }, { nbt: { Items: [ ] }, pos: [I; 2, 1, 1 ], state: 3 }, { pos: [I; 3, 1, 1 ], state: 2 }, { pos: [I; 4, 1, 1 ], state: 13 }, { pos: [I; -4, 4, 2 ], state: 14 }, { pos: [I; -3, 4, 2 ], state: 14 }, { pos: [I; -4, 2, 1 ], state: 7 }, { pos: [I; -2, 4, 2 ], state: 14 }, { pos: [I; -3, 2, 1 ], state: 2 }, { pos: [I; -1, 4, 2 ], state: 2 }, { pos: [I; -2, 2, 1 ], state: 2 }, { pos: [I; 1, 6, 3 ], state: 24 }, { nbt: { Items: [ ] }, pos: [I; 0, 4, 2 ], state: 45 }, { pos: [I; -1, 2, 1 ], state: 2 }, { nbt: { Items: [ ] }, pos: [I; 0, 2, 1 ], state: 10 } ], states: [ { Name: "minecraft:spruce_trapdoor", Properties: { facing: "south", half: "bottom", open: "true", powered: "false", waterlogged: "false" } }, { Name: "productivetrees:western_hemlock_planks" }, { Name: "chipped:double_packed_mud_bricks" }, { Name: "handcrafted:spruce_shelf", Properties: { facing: "west", shape: "single", type: "1" } }, { Name: "minecraft:dirt" }, { Name: "chipped:flowery_vine", Properties: { east: "false", north: "false", south: "false", up: "false", west: "true" } }, { Name: "minecraft:grass_block", Properties: { snowy: "false" } }, { Name: "chipped:flowery_vine", Properties: { east: "true", north: "false", south: "false", up: "false", west: "false" } }, { Name: "minecraft:spruce_stairs", Properties: { facing: "south", half: "top", shape: "straight", waterlogged: "false" } }, { Name: "farmersdelight:stove", Properties: { facing: "north", lit: "true" } }, { Name: "minecraft:barrel", Properties: { facing: "east", open: "false" } }, { Name: "farmersdelight:oak_cabinet", Properties: { facing: "north", open: "false" } }, { Name: "minecraft:spruce_trapdoor", Properties: { facing: "north", half: "bottom", open: "true", powered: "false", waterlogged: "false" } }, { Name: "chipped:apple_oak_leaves", Properties: { distance: "7", persistent: "true", waterlogged: "false" } }, { Name: "minecraft:spruce_stairs", Properties: { facing: "north", half: "bottom", shape: "straight", waterlogged: "false" } }, { Name: "productivetrees:sugar_maple_stairs", Properties: { facing: "north", half: "bottom", shape: "straight", waterlogged: "false" } }, { Name: "productivetrees:sugar_maple_planks" }, { Name: "farmersdelight:cooking_pot", Properties: { facing: "east", support: "none", waterlogged: "false" } }, { Name: "minecraft:spruce_stairs", Properties: { facing: "north", half: "top", shape: "straight", waterlogged: "false" } }, { Name: "minecraft:spruce_stairs", Properties: { facing: "south", half: "bottom", shape: "straight", waterlogged: "false" } }, { Name: "productivetrees:sugar_maple_stairs", Properties: { facing: "east", half: "bottom", shape: "inner_right", waterlogged: "false" } }, { Name: "farmersdelight:stove", Properties: { facing: "south", lit: "true" } }, { Name: "productivetrees:sugar_maple_stairs", Properties: { facing: "west", half: "bottom", shape: "inner_left", waterlogged: "false" } }, { Name: "productivetrees:sugar_maple_stairs", Properties: { facing: "south", half: "bottom", shape: "straight", waterlogged: "false" } }, { Name: "productivetrees:sugar_maple_slab", Properties: { type: "bottom", waterlogged: "false" } }, { Name: "handcrafted:kitchen_hood", Properties: { facing: "south", waterlogged: "false" } }, { Name: "handcrafted:kitchen_hood_pipe", Properties: { corner: "false", facing: "south", waterlogged: "false" } }, { Name: "minecraft:mud_brick_wall", Properties: { east: "none", north: "none", south: "none", up: "true", waterlogged: "false", west: "none" } }, { Name: "chipped:flowery_vine", Properties: { east: "false", north: "false", south: "true", up: "true", west: "false" } }, { Name: "chipped:flowery_vine", Properties: { east: "false", north: "false", south: "true", up: "false", west: "false" } }, { Name: "minecraft:jungle_fence", Properties: { east: "false", north: "false", south: "false", waterlogged: "false", west: "false" } }, { Name: "chipped:arched_red_stained_glass_pane_pillar", Properties: { east: "true", north: "false", south: "false", waterlogged: "false", west: "true" } }, { Name: "minecraft:spruce_slab", Properties: { type: "bottom", waterlogged: "false" } }, { Name: "productivetrees:sugar_maple_stairs", Properties: { facing: "west", half: "bottom", shape: "inner_right", waterlogged: "false" } }, { Name: "minecraft:spruce_slab", Properties: { type: "double", waterlogged: "false" } }, { Name: "supplementaries:item_shelf", Properties: { facing: "east", waterlogged: "false" } }, { Name: "productivetrees:pistachio_door", Properties: { facing: "east", half: "upper", hinge: "left", open: "true", powered: "false" } }, { Name: "mcwlights:copper_small_chandelier", Properties: { lit: "true" } }, { Name: "handcrafted:terracotta_crockery_combo", Properties: { facing: "south", waterlogged: "false" } }, { Name: "chipped:arched_red_stained_glass_pane_pillar", Properties: { east: "false", north: "true", south: "true", waterlogged: "false", west: "false" } }, { Name: "chipped:flowery_vine", Properties: { east: "false", north: "true", south: "false", up: "false", west: "false" } }, { Name: "productivetrees:pistachio_door", Properties: { facing: "east", half: "lower", hinge: "left", open: "true", powered: "false" } }, { Name: "handcrafted:spruce_table", Properties: { color: "none", shape: "single", waterlogged: "false" } }, { Name: "chipped:flowery_vine", Properties: { east: "false", north: "true", south: "false", up: "true", west: "false" } }, { Name: "handcrafted:spruce_bench", Properties: { color: "none", facing: "east", shape: "single", waterlogged: "false" } }, { Name: "farmersdelight:spruce_cabinet", Properties: { facing: "east", open: "false" } }, { Name: "chipped:flowery_vine", Properties: { east: "true", north: "false", south: "false", up: "true", west: "false" } } ] }, "minecraft:custom_name": "\"House #2\"", "minecraft:dyed_color": { rgb: 3949738 } }, count: 1, id: "bagofyurting:bag_of_yurting" } }
		{ id: "59CEFD83541F3A94", item: { components: { "bagofyurting:radius": 4, "bagofyurting:yurtdata": { data: [ { pos: [I; 2, 4, 2 ], state: 0 }, { pos: [I; 1, 2, 1 ], state: 1 }, { pos: [I; 0, 0, 0 ], state: 2 }, { pos: [I; -1, 0, 0 ], state: 2 }, { pos: [I; 3, 4, 2 ], state: 3 }, { pos: [I; 2, 2, 1 ], state: 0 }, { pos: [I; 1, 0, 0 ], state: 2 }, { pos: [I; -2, 0, 0 ], state: 4 }, { pos: [I; 3, 2, 1 ], state: 5 }, { pos: [I; 2, 0, 0 ], state: 4 }, { pos: [I; -3, 0, 0 ], state: 6 }, { nbt: { back_text: { color: "black", has_glowing_text: 0b, messages: [ "\"\"", "\"\"", "\"\"", "\"\"" ] }, front_text: { color: "black", has_glowing_text: 0b, messages: [ "\"\"", "\"\"", "\"\"", "\"\"" ] }, is_waxed: 0b }, pos: [I; 4, 2, 1 ], state: 7 }, { pos: [I; 3, 0, 0 ], state: 6 }, { pos: [I; -4, 0, 0 ], state: 6 }, { pos: [I; 4, 0, 0 ], state: 6 }, { pos: [I; -4, 3, 1 ], state: 8 }, { pos: [I; -2, 5, 2 ], state: 9 }, { pos: [I; -1, 5, 2 ], state: 2 }, { pos: [I; -2, 3, 1 ], state: 10 }, { nbt: { CookingTimes: [I; 0, 0, 0, 0 ], CookingTotalTimes: [I; 0, 0, 0, 0 ], Items: [ ] }, pos: [I; -3, 1, 0 ], state: 11 }, { pos: [I; 0, 5, 2 ], state: 2 }, { pos: [I; -2, 1, 0 ], state: 0 }, { pos: [I; 2, 7, 3 ], state: 12 }, { pos: [I; 1, 5, 2 ], state: 2 }, { pos: [I; -1, 1, 0 ], state: 13 }, { pos: [I; 2, 5, 2 ], state: 14 }, { pos: [I; 3, 5, 2 ], state: 15 }, { pos: [I; 2, 3, 1 ], state: 0 }, { pos: [I; 1, 1, 0 ], state: 16 }, { pos: [I; 3, 3, 1 ], state: 5 }, { pos: [I; 2, 1, 0 ], state: 0 }, { pos: [I; 4, 3, 1 ], state: 17 }, { pos: [I; 3, 1, 0 ], state: 18 }, { pos: [I; 4, 1, 0 ], state: 19 }, { pos: [I; -4, 4, 1 ], state: 20 }, { pos: [I; -3, 4, 1 ], state: 21 }, { pos: [I; -1, 6, 2 ], state: 22 }, { pos: [I; -2, 4, 1 ], state: 0 }, { pos: [I; -3, 2, 0 ], state: 23 }, { pos: [I; 0, 6, 2 ], state: 22 }, { pos: [I; -2, 2, 0 ], state: 0 }, { pos: [I; 2, 8, 3 ], state: 12 }, { pos: [I; 1, 6, 2 ], state: 22 }, { pos: [I; -1, 2, 0 ], state: 24 }, { nbt: { Items: [ ] }, pos: [I; 1, 4, 1 ], state: 25 }, { nbt: { back_text: { color: "black", has_glowing_text: 0b, messages: [ "\"\"", "\"\"", "\"\"", "\"\"" ] }, front_text: { color: "black", has_glowing_text: 0b, messages: [ "\"\"", "\"\"", "\"\"", "\"\"" ] }, is_waxed: 0b }, pos: [I; 3, 6, 2 ], state: 26 }, { pos: [I; 2, 4, 1 ], state: 0 }, { pos: [I; 1, 2, 0 ], state: 16 }, { pos: [I; 3, 4, 1 ], state: 5 }, { pos: [I; 2, 2, 0 ], state: 0 }, { pos: [I; 4, 4, 1 ], state: 17 }, { pos: [I; 3, 2, 0 ], state: 18 }, { pos: [I; -4, 3, 0 ], state: 8 }, { pos: [I; -2, 5, 1 ], state: 9 }, { pos: [I; -1, 5, 1 ], state: 2 }, { pos: [I; -2, 3, 0 ], state: 0 }, { pos: [I; 0, 5, 1 ], state: 2 }, { pos: [I; 1, 5, 1 ], state: 2 }, { pos: [I; 3, 7, 2 ], state: 15 }, { pos: [I; 2, 5, 1 ], state: 14 }, { pos: [I; 1, 3, 0 ], state: 16 }, { pos: [I; 4, 7, 2 ], state: 27 }, { pos: [I; 3, 5, 1 ], state: 5 }, { pos: [I; 2, 3, 0 ], state: 0 }, { pos: [I; 4, 5, 1 ], state: 17 }, { pos: [I; 3, 3, 0 ], state: 28 }, { pos: [I; -4, 4, 0 ], state: 20 }, { pos: [I; -1, 8, 2 ], state: 29 }, { pos: [I; -3, 4, 0 ], state: 21 }, { pos: [I; 0, 8, 2 ], state: 30 }, { pos: [I; -1, 6, 1 ], state: 22 }, { pos: [I; -2, 4, 0 ], state: 0 }, { pos: [I; 1, 8, 2 ], state: 30 }, { pos: [I; 0, 6, 1 ], state: 5 }, { pos: [I; 2, 8, 2 ], state: 30 }, { pos: [I; 1, 6, 1 ], state: 22 }, { pos: [I; 0, 4, 0 ], state: 31 }, { pos: [I; 3, 8, 2 ], state: 30 }, { nbt: { back_text: { color: "black", has_glowing_text: 0b, messages: [ "\"\"", "\"\"", "\"\"", "\"\"" ] }, front_text: { color: "black", has_glowing_text: 0b, messages: [ "\"\"", "\"\"", "\"\"", "\"\"" ] }, is_waxed: 0b }, pos: [I; 2, 6, 1 ], state: 32 }, { pos: [I; 1, 4, 0 ], state: 16 }, { pos: [I; 4, 8, 2 ], state: 29 }, { pos: [I; 3, 6, 1 ], state: 5 }, { pos: [I; 2, 4, 0 ], state: 0 }, { nbt: { back_text: { color: "black", has_glowing_text: 0b, messages: [ "\"\"", "\"\"", "\"\"", "\"\"" ] }, front_text: { color: "black", has_glowing_text: 0b, messages: [ "\"\"", "\"\"", "\"\"", "\"\"" ] }, is_waxed: 0b }, pos: [I; 4, 6, 1 ], state: 7 }, { pos: [I; 3, 4, 0 ], state: 3 }, { pos: [I; -2, 5, 0 ], state: 9 }, { pos: [I; 0, 7, 1 ], state: 5 }, { pos: [I; -1, 5, 0 ], state: 2 }, { pos: [I; 1, 7, 1 ], state: 33 }, { pos: [I; 0, 5, 0 ], state: 2 }, { pos: [I; 2, 7, 1 ], state: 33 }, { pos: [I; 1, 5, 0 ], state: 2 }, { pos: [I; 3, 7, 1 ], state: 5 }, { pos: [I; 2, 5, 0 ], state: 0 }, { pos: [I; 4, 7, 1 ], state: 17 }, { pos: [I; 3, 5, 0 ], state: 28 }, { pos: [I; -1, 8, 1 ], state: 30 }, { pos: [I; 0, 8, 1 ], state: 5 }, { pos: [I; -1, 6, 0 ], state: 22 }, { pos: [I; 1, 8, 1 ], state: 30 }, { pos: [I; 0, 6, 0 ], state: 22 }, { pos: [I; 2, 8, 1 ], state: 30 }, { pos: [I; 1, 6, 0 ], state: 0 }, { pos: [I; 3, 8, 1 ], state: 5 }, { pos: [I; 2, 6, 0 ], state: 0 }, { pos: [I; 4, 8, 1 ], state: 30 }, { nbt: { back_text: { color: "black", has_glowing_text: 0b, messages: [ "\"\"", "\"\"", "\"\"", "\"\"" ] }, front_text: { color: "black", has_glowing_text: 0b, messages: [ "\"\"", "\"\"", "\"\"", "\"\"" ] }, is_waxed: 0b }, pos: [I; 3, 6, 0 ], state: 34 }, { pos: [I; 0, 7, 0 ], state: 35 }, { pos: [I; 1, 7, 0 ], state: 0 }, { pos: [I; 2, 7, 0 ], state: 0 }, { pos: [I; 3, 7, 0 ], state: 36 }, { pos: [I; -1, 8, 0 ], state: 30 }, { pos: [I; 0, 8, 0 ], state: 30 }, { pos: [I; 1, 8, 0 ], state: 0 }, { pos: [I; 2, 8, 0 ], state: 0 }, { pos: [I; 3, 8, 0 ], state: 30 }, { pos: [I; 4, 8, 0 ], state: 30 }, { pos: [I; 4, 8, -3 ], state: 29 }, { pos: [I; 3, 8, -3 ], state: 30 }, { pos: [I; 2, 8, -3 ], state: 30 }, { pos: [I; 1, 6, -4 ], state: 37 }, { pos: [I; 1, 8, -3 ], state: 30 }, { pos: [I; 0, 6, -4 ], state: 37 }, { pos: [I; 0, 8, -3 ], state: 30 }, { pos: [I; -1, 6, -4 ], state: 37 }, { pos: [I; -1, 8, -3 ], state: 29 }, { pos: [I; 3, 5, -4 ], state: 37 }, { pos: [I; 2, 5, -4 ], state: 29 }, { pos: [I; 1, 5, -4 ], state: 29 }, { pos: [I; 0, 5, -4 ], state: 30 }, { pos: [I; -1, 5, -4 ], state: 29 }, { pos: [I; -2, 5, -4 ], state: 29 }, { pos: [I; -3, 5, -4 ], state: 37 }, { pos: [I; 3, 4, -4 ], state: 3 }, { pos: [I; 4, 8, -2 ], state: 30 }, { nbt: { back_text: { color: "black", has_glowing_text: 0b, messages: [ "\"\"", "\"\"", "\"\"", "\"\"" ] }, front_text: { color: "black", has_glowing_text: 0b, messages: [ "\"\"", "\"\"", "\"\"", "\"\"" ] }, is_waxed: 0b }, pos: [I; 3, 6, -3 ], state: 34 }, { pos: [I; 2, 4, -4 ], state: 38 }, { pos: [I; 3, 8, -2 ], state: 5 }, { pos: [I; 2, 8, -2 ], state: 30 }, { pos: [I; 1, 6, -3 ], state: 22 }, { pos: [I; 1, 8, -2 ], state: 30 }, { pos: [I; 0, 6, -3 ], state: 22 }, { pos: [I; 0, 8, -2 ], state: 5 }, { pos: [I; -1, 6, -3 ], state: 22 }, { pos: [I; -2, 4, -4 ], state: 39 }, { pos: [I; -1, 8, -2 ], state: 30 }, { pos: [I; -3, 4, -4 ], state: 21 }, { pos: [I; 3, 3, -4 ], state: 40 }, { pos: [I; 2, 3, -4 ], state: 41 }, { pos: [I; 3, 7, -2 ], state: 5 }, { pos: [I; 2, 5, -3 ], state: 14 }, { pos: [I; 1, 3, -4 ], state: 42 }, { pos: [I; 2, 7, -2 ], state: 43 }, { nbt: { back_text: { color: "black", has_glowing_text: 0b, messages: [ "\"\"", "\"\"", "\"\"", "\"\"" ] }, front_text: { color: "black", has_glowing_text: 0b, messages: [ "\"\"", "\"\"", "\"\"", "\"\"" ] }, is_waxed: 0b }, pos: [I; 0, 3, -4 ], state: 44 }, { pos: [I; 1, 7, -2 ], state: 43 }, { pos: [I; 0, 5, -3 ], state: 0 }, { pos: [I; -1, 3, -4 ], state: 42 }, { pos: [I; 0, 7, -2 ], state: 5 }, { pos: [I; -2, 5, -3 ], state: 9 }, { pos: [I; -3, 3, -4 ], state: 40 }, { pos: [I; 3, 2, -4 ], state: 40 }, { nbt: { back_text: { color: "black", has_glowing_text: 0b, messages: [ "\"\"", "\"\"", "\"\"", "\"\"" ] }, front_text: { color: "black", has_glowing_text: 0b, messages: [ "\"\"", "\"\"", "\"\"", "\"\"" ] }, is_waxed: 0b }, pos: [I; 4, 6, -2 ], state: 7 }, { pos: [I; 3, 4, -3 ], state: 3 }, { pos: [I; 2, 2, -4 ], state: 41 }, { pos: [I; 4, 8, -1 ], state: 30 }, { pos: [I; 3, 6, -2 ], state: 5 }, { pos: [I; 2, 4, -3 ], state: 5 }, { nbt: { back_text: { color: "black", has_glowing_text: 0b, messages: [ "\"\"", "\"\"", "\"\"", "\"\"" ] }, front_text: { color: "black", has_glowing_text: 0b, messages: [ "\"\"", "\"\"", "\"\"", "\"\"" ] }, is_waxed: 0b }, pos: [I; 1, 2, -4 ], state: 34 }, { pos: [I; 3, 8, -1 ], state: 30 }, { nbt: { back_text: { color: "black", has_glowing_text: 0b, messages: [ "\"\"", "\"\"", "\"\"", "\"\"" ] }, front_text: { color: "black", has_glowing_text: 0b, messages: [ "\"\"", "\"\"", "\"\"", "\"\"" ] }, is_waxed: 0b }, pos: [I; 2, 6, -2 ], state: 32 }, { pos: [I; 1, 4, -3 ], state: 0 }, { pos: [I; 2, 8, -1 ], state: 0 }, { pos: [I; 1, 6, -2 ], state: 22 }, { pos: [I; 0, 4, -3 ], state: 0 }, { nbt: { back_text: { color: "black", has_glowing_text: 0b, messages: [ "\"\"", "\"\"", "\"\"", "\"\"" ] }, front_text: { color: "black", has_glowing_text: 0b, messages: [ "\"\"", "\"\"", "\"\"", "\"\"" ] }, is_waxed: 0b }, pos: [I; -1, 2, -4 ], state: 34 }, { pos: [I; 1, 8, -1 ], state: 0 }, { pos: [I; 0, 6, -2 ], state: 5 }, { pos: [I; -1, 4, -3 ], state: 0 }, { pos: [I; 0, 8, -1 ], state: 30 }, { pos: [I; -1, 6, -2 ], state: 22 }, { pos: [I; -2, 4, -3 ], state: 5 }, { pos: [I; -3, 2, -4 ], state: 40 }, { pos: [I; -1, 8, -1 ], state: 30 }, { pos: [I; -3, 4, -3 ], state: 21 }, { pos: [I; 4, 1, -4 ], state: 45 }, { pos: [I; 3, 1, -4 ], state: 46 }, { pos: [I; 3, 3, -3 ], state: 47 }, { pos: [I; 2, 1, -4 ], state: 41 }, { pos: [I; 3, 5, -2 ], state: 5 }, { pos: [I; 2, 3, -3 ], state: 5 }, { pos: [I; 1, 1, -4 ], state: 41 }, { pos: [I; 3, 7, -1 ], state: 36 }, { pos: [I; 2, 5, -2 ], state: 14 }, { pos: [I; 1, 3, -3 ], state: 0 }, { pos: [I; 2, 7, -1 ], state: 0 }, { pos: [I; 1, 5, -2 ], state: 2 }, { pos: [I; 0, 3, -3 ], state: 0 }, { pos: [I; 1, 7, -1 ], state: 0 }, { pos: [I; 0, 5, -2 ], state: 2 }, { pos: [I; -1, 3, -3 ], state: 0 }, { pos: [I; -2, 1, -4 ], state: 18 }, { pos: [I; 0, 7, -1 ], state: 35 }, { pos: [I; -1, 5, -2 ], state: 2 }, { pos: [I; -2, 3, -3 ], state: 5 }, { pos: [I; -3, 1, -4 ], state: 46 }, { pos: [I; -2, 5, -2 ], state: 9 }, { pos: [I; -4, 1, -4 ], state: 45 }, { nbt: { back_text: { color: "black", has_glowing_text: 0b, messages: [ "\"\"", "\"\"", "\"\"", "\"\"" ] }, front_text: { color: "black", has_glowing_text: 0b, messages: [ "\"\"", "\"\"", "\"\"", "\"\"" ] }, is_waxed: 0b }, pos: [I; -4, 3, -3 ], state: 34 }, { pos: [I; 4, 0, -4 ], state: 6 }, { pos: [I; -4, 0, 4 ], state: 6 }, { pos: [I; 3, 0, -4 ], state: 6 }, { pos: [I; 4, 4, -2 ], state: 17 }, { pos: [I; 3, 2, -3 ], state: 47 }, { pos: [I; -3, 0, 4 ], state: 6 }, { pos: [I; 2, 0, -4 ], state: 6 }, { pos: [I; 3, 4, -2 ], state: 5 }, { pos: [I; 2, 2, -3 ], state: 5 }, { pos: [I; -2, 0, 4 ], state: 6 }, { pos: [I; 1, 0, -4 ], state: 6 }, { nbt: { back_text: { color: "black", has_glowing_text: 0b, messages: [ "\"\"", "\"\"", "\"\"", "\"\"" ] }, front_text: { color: "black", has_glowing_text: 0b, messages: [ "\"\"", "\"\"", "\"\"", "\"\"" ] }, is_waxed: 0b }, pos: [I; 3, 6, -1 ], state: 26 }, { pos: [I; 2, 4, -2 ], state: 0 }, { pos: [I; 1, 2, -3 ], state: 0 }, { pos: [I; -1, 0, 4 ], state: 6 }, { pos: [I; 0, 0, -4 ], state: 6 }, { pos: [I; 2, 6, -1 ], state: 0 }, { pos: [I; 0, 2, -3 ], state: 48 }, { pos: [I; 0, 0, 4 ], state: 6 }, { pos: [I; -1, 0, -4 ], state: 6 }, { pos: [I; 1, 6, -1 ], state: 0 }, { pos: [I; -1, 2, -3 ], state: 0 }, { pos: [I; 1, 0, 4 ], state: 6 }, { pos: [I; -2, 0, -4 ], state: 6 }, { pos: [I; 0, 6, -1 ], state: 22 }, { nbt: { Items: [ ] }, pos: [I; -1, 4, -2 ], state: 49 }, { pos: [I; -2, 2, -3 ], state: 5 }, { pos: [I; 2, 0, 4 ], state: 6 }, { pos: [I; -3, 0, -4 ], state: 6 }, { pos: [I; -1, 6, -1 ], state: 22 }, { pos: [I; -2, 4, -2 ], state: 0 }, { pos: [I; -3, 2, -3 ], state: 18 }, { pos: [I; 3, 0, 4 ], state: 6 }, { pos: [I; -4, 0, -4 ], state: 6 }, { pos: [I; -3, 4, -2 ], state: 21 }, { pos: [I; 4, 0, 4 ], state: 6 }, { pos: [I; 4, 3, -2 ], state: 17 }, { pos: [I; 3, 1, -3 ], state: 50 }, { pos: [I; -3, 1, 4 ], state: 46 }, { pos: [I; 3, 3, -2 ], state: 5 }, { pos: [I; -2, 1, 4 ], state: 51 }, { pos: [I; 2, 1, -3 ], state: 5 }, { pos: [I; 3, 5, -1 ], state: 28 }, { pos: [I; 2, 3, -2 ], state: 0 }, { pos: [I; -1, 1, 4 ], state: 45 }, { pos: [I; 1, 1, -3 ], state: 0 }, { pos: [I; 2, 5, -1 ], state: 0 }, { pos: [I; 1, 3, -2 ], state: 52 }, { pos: [I; 0, 1, -3 ], state: 53 }, { pos: [I; 1, 5, -1 ], state: 2 }, { pos: [I; 1, 1, 4 ], state: 54 }, { pos: [I; -1, 1, -3 ], state: 0 }, { pos: [I; 0, 5, -1 ], state: 2 }, { nbt: { Items: [ ] }, pos: [I; -1, 3, -2 ], state: 55 }, { pos: [I; 2, 1, 4 ], state: 18 }, { pos: [I; -2, 1, -3 ], state: 5 }, { pos: [I; -1, 5, -1 ], state: 2 }, { pos: [I; -2, 3, -2 ], state: 0 }, { pos: [I; -3, 1, -3 ], state: 18 }, { pos: [I; 3, 1, 4 ], state: 46 }, { pos: [I; -2, 5, -1 ], state: 9 }, { pos: [I; -3, 3, -2 ], state: 30 }, { pos: [I; -4, 3, -2 ], state: 29 }, { pos: [I; 4, 0, -3 ], state: 6 }, { pos: [I; 4, 2, -2 ], state: 56 }, { pos: [I; -3, 2, 4 ], state: 40 }, { pos: [I; -4, 0, 3 ], state: 6 }, { pos: [I; 3, 0, -3 ], state: 6 }, { nbt: { back_text: { color: "black", has_glowing_text: 0b, messages: [ "\"\"", "\"\"", "\"\"", "\"\"" ] }, front_text: { color: "black", has_glowing_text: 0b, messages: [ "\"\"", "\"\"", "\"\"", "\"\"" ] }, is_waxed: 0b }, pos: [I; -2, 2, 4 ], state: 26 }, { pos: [I; 3, 2, -2 ], state: 5 }, { pos: [I; -3, 0, 3 ], state: 6 }, { pos: [I; 2, 0, -3 ], state: 4 }, { pos: [I; 3, 4, -1 ], state: 3 }, { pos: [I; 2, 2, -2 ], state: 0 }, { pos: [I; -2, 0, 3 ], state: 4 }, { pos: [I; 1, 0, -3 ], state: 4 }, { pos: [I; 2, 4, -1 ], state: 0 }, { pos: [I; 1, 2, -2 ], state: 8 }, { pos: [I; -1, 0, 3 ], state: 4 }, { pos: [I; 0, 0, -3 ], state: 2 }, { pos: [I; 1, 2, 4 ], state: 57 }, { pos: [I; 0, 0, 3 ], state: 4 }, { pos: [I; -1, 0, -3 ], state: 4 }, { nbt: { back_text: { color: "black", has_glowing_text: 0b, messages: [ "\"\"", "\"\"", "\"\"", "\"\"" ] }, front_text: { color: "black", has_glowing_text: 0b, messages: [ "\"\"", "\"\"", "\"\"", "\"\"" ] }, is_waxed: 0b }, pos: [I; 2, 2, 4 ], state: 26 }, { nbt: { Items: [ ] }, pos: [I; -1, 2, -2 ], state: 58 }, { pos: [I; 1, 0, 3 ], state: 4 }, { pos: [I; -2, 0, -3 ], state: 4 }, { pos: [I; 3, 2, 4 ], state: 40 }, { pos: [I; -2, 2, -2 ], state: 0 }, { pos: [I; 2, 0, 3 ], state: 4 }, { pos: [I; -3, 0, -3 ], state: 6 }, { pos: [I; -2, 4, -1 ], state: 0 }, { pos: [I; -3, 2, -2 ], state: 59 }, { pos: [I; 3, 0, 3 ], state: 6 }, { pos: [I; -4, 0, -3 ], state: 6 }, { pos: [I; -3, 4, -1 ], state: 21 }, { pos: [I; -4, 2, -2 ], state: 40 }, { pos: [I; 4, 0, 3 ], state: 6 }, { pos: [I; -4, 4, -1 ], state: 20 }, { pos: [I; -3, 3, 4 ], state: 40 }, { pos: [I; -4, 1, 3 ], state: 45 }, { pos: [I; 4, 1, -2 ], state: 17 }, { pos: [I; -3, 1, 3 ], state: 60 }, { pos: [I; 3, 1, -2 ], state: 5 }, { pos: [I; -1, 3, 4 ], state: 61 }, { pos: [I; 3, 3, -1 ], state: 28 }, { pos: [I; -2, 1, 3 ], state: 5 }, { pos: [I; 2, 1, -2 ], state: 0 }, { pos: [I; 2, 3, -1 ], state: 0 }, { pos: [I; -1, 1, 3 ], state: 0 }, { pos: [I; 1, 3, 4 ], state: 61 }, { pos: [I; 1, 3, -1 ], state: 62 }, { pos: [I; 0, 1, 3 ], state: 0 }, { pos: [I; 1, 1, 3 ], state: 0 }, { nbt: { Items: [ ] }, pos: [I; -1, 1, -2 ], state: 63 }, { pos: [I; 3, 3, 4 ], state: 40 }, { pos: [I; 2, 1, 3 ], state: 5 }, { pos: [I; -2, 1, -2 ], state: 0 }, { pos: [I; -2, 3, -1 ], state: 10 }, { pos: [I; -3, 1, -2 ], state: 54 }, { pos: [I; 4, 1, 3 ], state: 45 }, { pos: [I; -4, 1, -2 ], state: 46 }, { pos: [I; -4, 3, -1 ], state: 8 }, { pos: [I; -3, 4, 4 ], state: 21 }, { pos: [I; 4, 0, -2 ], state: 6 }, { pos: [I; -2, 4, 4 ], state: 39 }, { nbt: { back_text: { color: "black", has_glowing_text: 0b, messages: [ "\"\"", "\"\"", "\"\"", "\"\"" ] }, front_text: { color: "black", has_glowing_text: 0b, messages: [ "\"\"", "\"\"", "\"\"", "\"\"" ] }, is_waxed: 0b }, pos: [I; -3, 2, 3 ], state: 32 }, { pos: [I; -4, 0, 2 ], state: 6 }, { pos: [I; 3, 0, -2 ], state: 4 }, { pos: [I; 3, 2, -1 ], state: 15 }, { pos: [I; -2, 2, 3 ], state: 5 }, { pos: [I; -3, 0, 2 ], state: 6 }, { pos: [I; 2, 0, -2 ], state: 4 }, { pos: [I; 0, 4, 4 ], state: 64 }, { pos: [I; -1, 2, 3 ], state: 0 }, { pos: [I; 2, 2, -1 ], state: 0 }, { pos: [I; -2, 0, 2 ], state: 4 }, { pos: [I; 1, 0, -2 ], state: 2 }, { pos: [I; 0, 2, 3 ], state: 65 }, { pos: [I; 1, 2, -1 ], state: 8 }, { pos: [I; -1, 0, 2 ], state: 2 }, { pos: [I; 0, 0, -2 ], state: 2 }, { pos: [I; 2, 4, 4 ], state: 38 }, { nbt: { camo: { type: "framedblocks:empty" }, glowing: 0b, intangible: 0b, reinforced: 0b, updated: 3b }, pos: [I; 0, 2, -1 ], state: 66 }, { pos: [I; 1, 2, 3 ], state: 0 }, { pos: [I; 0, 0, 2 ], state: 2 }, { pos: [I; -1, 0, -2 ], state: 2 }, { pos: [I; 3, 4, 4 ], state: 3 }, { pos: [I; 2, 2, 3 ], state: 5 }, { pos: [I; 1, 0, 2 ], state: 2 }, { pos: [I; -2, 0, -2 ], state: 4 }, { nbt: { back_text: { color: "black", has_glowing_text: 0b, messages: [ "\"\"", "\"\"", "\"\"", "\"\"" ] }, front_text: { color: "black", has_glowing_text: 0b, messages: [ "\"\"", "\"\"", "\"\"", "\"\"" ] }, is_waxed: 0b }, pos: [I; 3, 2, 3 ], state: 7 }, { pos: [I; -2, 2, -1 ], state: 10 }, { pos: [I; 2, 0, 2 ], state: 4 }, { pos: [I; -3, 0, -2 ], state: 6 }, { pos: [I; -3, 2, -1 ], state: 67 }, { pos: [I; 3, 0, 2 ], state: 6 }, { pos: [I; -4, 0, -2 ], state: 6 }, { pos: [I; 4, 0, 2 ], state: 6 }, { pos: [I; -3, 5, 4 ], state: 37 }, { nbt: { back_text: { color: "black", has_glowing_text: 0b, messages: [ "\"\"", "\"\"", "\"\"", "\"\"" ] }, front_text: { color: "black", has_glowing_text: 0b, messages: [ "\"\"", "\"\"", "\"\"", "\"\"" ] }, is_waxed: 0b }, pos: [I; -4, 3, 3 ], state: 26 }, { pos: [I; -2, 5, 4 ], state: 29 }, { pos: [I; -4, 1, 2 ], state: 46 }, { pos: [I; -1, 5, 4 ], state: 29 }, { pos: [I; -2, 3, 3 ], state: 5 }, { pos: [I; -3, 1, 2 ], state: 68 }, { pos: [I; 3, 1, -1 ], state: 69 }, { pos: [I; 0, 5, 4 ], state: 30 }, { pos: [I; -1, 3, 3 ], state: 0 }, { pos: [I; -2, 1, 2 ], state: 0 }, { pos: [I; 2, 1, -1 ], state: 0 }, { pos: [I; 1, 5, 4 ], state: 29 }, { pos: [I; 0, 3, 3 ], state: 65 }, { pos: [I; -1, 1, 2 ], state: 70 }, { pos: [I; 1, 1, -1 ], state: 71 }, { pos: [I; 2, 5, 4 ], state: 29 }, { pos: [I; 1, 3, 3 ], state: 0 }, { nbt: { camo: { type: "framedblocks:empty" }, glowing: 0b, intangible: 0b, reinforced: 0b, updated: 3b }, pos: [I; 0, 1, -1 ], state: 66 }, { pos: [I; 3, 5, 4 ], state: 37 }, { pos: [I; 2, 3, 3 ], state: 5 }, { nbt: { CookingTimes: [I; 0, 0, 0, 0, 0, 0 ], CookingTotalTimes: [I; 0, 0, 0, 0, 0, 0 ], Inventory: { Items: [ ], Size: 6 } }, pos: [I; 1, 1, 2 ], state: 72 }, { pos: [I; 2, 1, 2 ], state: 0 }, { pos: [I; -2, 1, -1 ], state: 0 }, { pos: [I; 3, 1, 2 ], state: 18 }, { nbt: { Items: [ ] }, pos: [I; -3, 1, -1 ], state: 73 }, { pos: [I; -4, 1, -1 ], state: 74 }, { pos: [I; -3, 4, 3 ], state: 21 }, { pos: [I; -4, 2, 2 ], state: 40 }, { pos: [I; 4, 0, -1 ], state: 6 }, { pos: [I; -1, 6, 4 ], state: 37 }, { pos: [I; -2, 4, 3 ], state: 5 }, { pos: [I; -3, 2, 2 ], state: 60 }, { pos: [I; -4, 0, 1 ], state: 6 }, { pos: [I; 3, 0, -1 ], state: 6 }, { pos: [I; 0, 6, 4 ], state: 37 }, { pos: [I; -1, 4, 3 ], state: 0 }, { pos: [I; -2, 2, 2 ], state: 0 }, { pos: [I; -3, 0, 1 ], state: 4 }, { pos: [I; 2, 0, -1 ], state: 4 }, { pos: [I; 1, 6, 4 ], state: 37 }, { pos: [I; 0, 4, 3 ], state: 0 }, { pos: [I; -2, 0, 1 ], state: 4 }, { pos: [I; 1, 0, -1 ], state: 2 }, { pos: [I; 1, 4, 3 ], state: 0 }, { pos: [I; -1, 0, 1 ], state: 2 }, { pos: [I; 0, 0, -1 ], state: 2 }, { pos: [I; 2, 4, 3 ], state: 5 }, { nbt: { Container: { }, CookTime: 0, CookTimeTotal: 0, Inventory: { Items: [ ], Size: 9 }, RecipesUsed: { } }, pos: [I; 1, 2, 2 ], state: 75 }, { pos: [I; 0, 0, 1 ], state: 2 }, { pos: [I; -1, 0, -1 ], state: 2 }, { pos: [I; 3, 4, 3 ], state: 3 }, { pos: [I; 2, 2, 2 ], state: 0 }, { pos: [I; 1, 0, 1 ], state: 2 }, { pos: [I; -2, 0, -1 ], state: 4 }, { pos: [I; 3, 2, 2 ], state: 36 }, { pos: [I; 2, 0, 1 ], state: 4 }, { pos: [I; -3, 0, -1 ], state: 4 }, { pos: [I; 3, 0, 1 ], state: 4 }, { pos: [I; -4, 0, -1 ], state: 6 }, { pos: [I; 4, 0, 1 ], state: 6 }, { pos: [I; -4, 3, 2 ], state: 29 }, { pos: [I; -2, 5, 3 ], state: 9 }, { pos: [I; -3, 3, 2 ], state: 30 }, { pos: [I; -1, 5, 3 ], state: 2 }, { pos: [I; -2, 3, 2 ], state: 0 }, { nbt: { Items: [ ] }, pos: [I; -3, 1, 1 ], state: 73 }, { pos: [I; 0, 5, 3 ], state: 0 }, { pos: [I; -2, 1, 1 ], state: 0 }, { pos: [I; 1, 5, 3 ], state: 2 }, { nbt: { Items: [ ] }, pos: [I; -1, 1, 1 ], state: 76 }, { nbt: { BurnTime: 0, CookTime: 0, CookTimeTotal: 0, Items: [ ], RecipesUsed: { } }, pos: [I; 2, 5, 3 ], state: 77 }, { pos: [I; 2, 3, 2 ], state: 0 }, { nbt: { Items: [ ] }, pos: [I; 1, 1, 1 ], state: 78 }, { pos: [I; 3, 3, 2 ], state: 79 }, { pos: [I; 2, 1, 1 ], state: 0 }, { pos: [I; 3, 1, 1 ], state: 5 }, { pos: [I; 4, 1, 1 ], state: 18 }, { pos: [I; -3, 4, 2 ], state: 21 }, { pos: [I; -1, 6, 3 ], state: 22 }, { pos: [I; -2, 4, 2 ], state: 0 }, { pos: [I; -3, 2, 1 ], state: 80 }, { pos: [I; 0, 6, 3 ], state: 22 }, { pos: [I; -2, 2, 1 ], state: 10 }, { pos: [I; 1, 6, 3 ], state: 22 }, { pos: [I; -1, 2, 1 ], state: 81 }, { pos: [I; 2, 6, 3 ], state: 12 } ], states: [ { Name: "chipped:small_diorite_bricks" }, { Name: "farmersdelight:roast_chicken_block", Properties: { facing: "east", servings: "4" } }, { Name: "chipped:shifted_oak_planks" }, { Name: "minecraft:spruce_stairs", Properties: { facing: "west", half: "bottom", shape: "straight", waterlogged: "false" } }, { Name: "minecraft:dirt" }, { Name: "minecraft:stripped_spruce_log", Properties: { axis: "y" } }, { Name: "minecraft:grass_block", Properties: { snowy: "false" } }, { Name: "minecraft:spruce_wall_sign", Properties: { facing: "east", waterlogged: "false" } }, { Name: "minecraft:spruce_trapdoor", Properties: { facing: "west", half: "top", open: "false", powered: "false", waterlogged: "false" } }, { Name: "minecraft:diorite_stairs", Properties: { facing: "east", half: "bottom", shape: "straight", waterlogged: "false" } }, { Name: "chipped:circular_white_stained_glass_pane", Properties: { east: "false", north: "true", south: "true", waterlogged: "false", west: "false" } }, { Name: "minecraft:campfire", Properties: { facing: "east", lit: "false", signal_fire: "false", waterlogged: "false" } }, { Name: "minecraft:tuff_brick_wall", Properties: { east: "none", north: "none", south: "none", up: "true", waterlogged: "false", west: "none" } }, { Name: "handcrafted:spruce_corner_trim", Properties: { facing: "west", half: "top", trim: "normal", waterlogged: "false" } }, { Name: "minecraft:diorite_stairs", Properties: { facing: "west", half: "bottom", shape: "straight", waterlogged: "false" } }, { Name: "chipped:ivy_vine", Properties: { east: "false", north: "true", south: "false", up: "false", west: "false" } }, { Name: "minecraft:spruce_trapdoor", Properties: { facing: "north", half: "bottom", open: "true", powered: "false", waterlogged: "false" } }, { Name: "chipped:ivy_vine", Properties: { east: "false", north: "false", south: "false", up: "false", west: "true" } }, { Name: "chipped:white_flower_oak_leaves", Properties: { distance: "1", persistent: "true", waterlogged: "false" } }, { Name: "chipped:ivy_vine", Properties: { east: "false", north: "false", south: "true", up: "false", west: "true" } }, { Name: "minecraft:spruce_trapdoor", Properties: { facing: "west", half: "bottom", open: "false", powered: "false", waterlogged: "false" } }, { Name: "minecraft:spruce_stairs", Properties: { facing: "east", half: "bottom", shape: "straight", waterlogged: "false" } }, { Name: "minecraft:diorite_slab", Properties: { type: "bottom", waterlogged: "false" } }, { Name: "minecraft:spruce_button", Properties: { face: "wall", facing: "west", powered: "false" } }, { Name: "minecraft:potted_lily_of_the_valley" }, { Name: "handcrafted:spruce_cupboard", Properties: { facing: "west", type: "1" } }, { Name: "minecraft:spruce_wall_sign", Properties: { facing: "south", waterlogged: "false" } }, { Name: "chipped:ivy_vine", Properties: { east: "false", north: "false", south: "false", up: "true", west: "false" } }, { Name: "minecraft:spruce_button", Properties: { face: "wall", facing: "east", powered: "false" } }, { Name: "minecraft:spruce_slab", Properties: { type: "double", waterlogged: "false" } }, { Name: "minecraft:spruce_slab", Properties: { type: "top", waterlogged: "false" } }, { Name: "mcwlights:iron_small_chandelier", Properties: { lit: "true" } }, { Name: "minecraft:spruce_wall_sign", Properties: { facing: "west", waterlogged: "false" } }, { Name: "chipped:slotted_spruce_trapdoor", Properties: { facing: "south", half: "top", open: "true", powered: "false", waterlogged: "false" } }, { Name: "minecraft:spruce_wall_sign", Properties: { facing: "north", waterlogged: "false" } }, { Name: "chipped:slotted_spruce_trapdoor", Properties: { facing: "west", half: "top", open: "true", powered: "false", waterlogged: "false" } }, { Name: "chipped:slotted_spruce_trapdoor", Properties: { facing: "east", half: "top", open: "true", powered: "false", waterlogged: "false" } }, { Name: "minecraft:spruce_slab", Properties: { type: "bottom", waterlogged: "false" } }, { Name: "minecraft:spruce_stairs", Properties: { facing: "east", half: "top", shape: "straight", waterlogged: "false" } }, { Name: "minecraft:spruce_stairs", Properties: { facing: "west", half: "top", shape: "straight", waterlogged: "false" } }, { Name: "minecraft:spruce_fence", Properties: { east: "false", north: "false", south: "false", waterlogged: "false", west: "false" } }, { Name: "chipped:leafy_vine", Properties: { east: "false", north: "false", south: "true", up: "false", west: "false" } }, { Name: "minecraft:spruce_button", Properties: { face: "wall", facing: "north", powered: "false" } }, { Name: "chipped:slotted_spruce_trapdoor", Properties: { facing: "north", half: "top", open: "true", powered: "false", waterlogged: "false" } }, { Name: "farmersdelight:white_wall_hanging_canvas_sign", Properties: { facing: "west", waterlogged: "false" } }, { Name: "farmersdelight:wild_cabbages" }, { Name: "minecraft:mud_brick_wall", Properties: { east: "none", north: "none", south: "none", up: "true", waterlogged: "false", west: "none" } }, { Name: "chipped:leafy_vine", Properties: { east: "false", north: "false", south: "true", up: "false", west: "true" } }, { Name: "chipped:supported_spruce_door", Properties: { facing: "south", half: "upper", hinge: "left", open: "true", powered: "false" } }, { Name: "mcwfurnitures:stripped_spruce_bookshelf", Properties: { connection: "top", facing: "east" } }, { Name: "minecraft:decorated_pot", Properties: { cracked: "false", facing: "west", waterlogged: "false" } }, { Name: "chipped:leafy_vine", Properties: { east: "false", north: "true", south: "false", up: "false", west: "false" } }, { Name: "handcrafted:spruce_fancy_bed", Properties: { color: "white", facing: "north", occupied: "false", part: "head", shape: "single" } }, { Name: "chipped:supported_spruce_door", Properties: { facing: "south", half: "lower", hinge: "left", open: "true", powered: "false" } }, { Name: "chipped:white_flower_oak_leaves", Properties: { distance: "2", persistent: "true", waterlogged: "false" } }, { Name: "mcwfurnitures:stripped_spruce_bookshelf", Properties: { connection: "middle", facing: "east" } }, { Name: "mcwlights:bell_wall_lantern", Properties: { facing: "east" } }, { Name: "chipped:white_flower_oak_leaves", Properties: { distance: "3", persistent: "true", waterlogged: "false" } }, { Name: "mcwfurnitures:stripped_spruce_bookshelf", Properties: { connection: "bottom", facing: "east" } }, { Name: "chipped:ivy_vine", Properties: { east: "true", north: "true", south: "false", up: "false", west: "false" } }, { Name: "chipped:leafy_vine", Properties: { east: "true", north: "false", south: "false", up: "false", west: "false" } }, { Name: "minecraft:spruce_button", Properties: { face: "wall", facing: "south", powered: "false" } }, { Name: "handcrafted:spruce_fancy_bed", Properties: { color: "white", facing: "north", occupied: "false", part: "foot", shape: "single" } }, { Name: "mcwfurnitures:stripped_spruce_lower_bookshelf_drawer", Properties: { connection: "single", facing: "east" } }, { Name: "mcwlights:bell_wall_lantern", Properties: { facing: "south" } }, { Name: "chipped:circular_white_stained_glass_pane", Properties: { east: "true", north: "false", south: "false", waterlogged: "false", west: "true" } }, { Name: "framedblocks:framed_ladder", Properties: { facing: "east", glowing: "false", propagates_skylight: "false", waterlogged: "false" } }, { Name: "handcrafted:terracotta_medium_pot" }, { Name: "chipped:leafy_vine", Properties: { east: "true", north: "true", south: "false", up: "false", west: "false" } }, { Name: "chipped:ivy_vine", Properties: { east: "false", north: "true", south: "true", up: "false", west: "true" } }, { Name: "handcrafted:spruce_bench", Properties: { color: "none", facing: "north", shape: "single", waterlogged: "false" } }, { Name: "handcrafted:terracotta_thin_pot" }, { Name: "farmersdelight:stove", Properties: { facing: "west", lit: "true" } }, { Name: "minecraft:barrel", Properties: { facing: "west", open: "false" } }, { Name: "minecraft:spruce_pressure_plate", Properties: { powered: "false" } }, { Name: "farmersdelight:cooking_pot", Properties: { facing: "east", support: "none", waterlogged: "false" } }, { Name: "handcrafted:spruce_side_table", Properties: { color: "none", facing: "east", waterlogged: "false" } }, { Name: "handcrafted:oven", Properties: { facing: "west", lit: "false" } }, { Name: "handcrafted:spruce_counter", Properties: { counter: "calcite", facing: "west", type: "1" } }, { Name: "chipped:slotted_spruce_trapdoor", Properties: { facing: "east", half: "bottom", open: "true", powered: "false", waterlogged: "false" } }, { Name: "minecraft:spruce_button", Properties: { face: "floor", facing: "east", powered: "false" } }, { Name: "handcrafted:white_plate", Properties: { facing: "east", pieces: "1", waterlogged: "false" } } ] }, "minecraft:custom_name": "\"House #3\"", "minecraft:dyed_color": { rgb: 6192150 } }, count: 1, id: "bagofyurting:bag_of_yurting" } }
	]
	use_title: true
}
